<robot name="ergoCub">
  <link name="root_link">
    <inertial>
      <origin xyz="0.00247235 -0.000154174 0.02343999999999999" rpy="0 0 1.5707963267948966"/>
      <mass value="2.5751"/>
      <inertia ixx="0.003995407240333586" ixy="-1.1192406042527262e-06" ixz="1.2734094198380252e-05" iyy="0.005135293091622795" iyz="-2.1041821887864638e-05" izz="0.0032992984093018645"/>
    </inertial>
    <visual>
      <origin xyz="0 -5e-05 0.1785" rpy="0 0 1.5707963267948966"/>
      <geometry>
        <mesh filename="package://ergoCub/meshes/simmechanics/sim_ecub_root_link_prt.stl" scale="0.001 0.001 0.001"/>
      </geometry>
      <material name="root_link_color">
        <color rgba="0.9 0.9 0.9 1"/>
      </material>
    </visual>
    <collision>
      <origin xyz="0 -5e-05 0.1785" rpy="0 0 1.5707963267948966"/>
      <geometry>
        <mesh filename="package://ergoCub/meshes/simmechanics/sim_ecub_root_link_prt.stl" scale="0.001 0.001 0.001"/>
      </geometry>
    </collision>
  </link>
  <link name="torso_1">
    <inertial>
      <origin xyz="-0.00957343 0.000567919 0.0824068" rpy="0 0 1.5707963267948966"/>
      <mass value="1.6998"/>
      <inertia ixx="0.0059891428915159525" ixy="5.619934913548823e-06" ixz="-1.0915600236634618e-05" iyy="0.004907587954502521" iyz="0.0006115355707567336" izz="0.0024873794644898932"/>
    </inertial>
    <visual>
      <origin xyz="0 -5.000000000001411e-05 0.11800000000000006" rpy="0 0 1.5707963267948966"/>
      <geometry>
        <mesh filename="package://ergoCub/meshes/simmechanics/sim_ecub_torso_1_prt.stl" scale="0.001 0.001 0.001"/>
      </geometry>
      <material name="torso_1_color">
        <color rgba="0.9 0.9 0.9 1"/>
      </material>
    </visual>
    <collision>
      <origin xyz="0 -5.000000000001411e-05 0.11800000000000006" rpy="0 0 1.5707963267948966"/>
      <geometry>
        <mesh filename="package://ergoCub/meshes/simmechanics/sim_ecub_torso_1_prt.stl" scale="0.001 0.001 0.001"/>
      </geometry>
    </collision>
  </link>
  <joint name="torso_roll" type="revolute">
    <origin xyz="0 0 0.060499999999999984" rpy="0 0 0"/>
    <axis xyz="-1.0 0.0 0.0"/>
    <parent link="root_link"/>
    <child link="torso_1"/>
    <limit effort="50000" lower="-0.4014257279586958" upper="0.4014257279586958" velocity="120.0"/>
    <dynamics damping="2.0" friction="0.0"/>
  </joint>
  <link name="torso_2">
    <inertial>
      <origin xyz="0.00157247 0.00359887 0.02601949999999994" rpy="0 0 1.5707963267948966"/>
      <mass value="0.77098"/>
      <inertia ixx="0.0007298596380411338" ixy="-4.561572170973237e-06" ixz="7.634108357925756e-05" iyy="0.0013764005229996471" iyz="5.902023810665052e-06" izz="0.001252623969493578"/>
    </inertial>
    <visual>
      <origin xyz="0 -4.9999999999999894e-05 0" rpy="0 0 1.5707963267948966"/>
      <geometry>
        <mesh filename="package://ergoCub/meshes/simmechanics/sim_ecub_torso_2_prt.stl" scale="0.001 0.001 0.001"/>
      </geometry>
      <material name="torso_2_color">
        <color rgba="0.9 0.9 0.9 1"/>
      </material>
    </visual>
    <collision>
      <origin xyz="0 -4.9999999999999894e-05 0" rpy="0 0 1.5707963267948966"/>
      <geometry>
        <mesh filename="package://ergoCub/meshes/simmechanics/sim_ecub_torso_2_prt.stl" scale="0.001 0.001 0.001"/>
      </geometry>
    </collision>
  </link>
  <joint name="torso_pitch" type="revolute">
    <origin xyz="0 0 0.11800000000000006" rpy="0 0 0"/>
    <axis xyz="0.0 1.0 0.0"/>
    <parent link="torso_1"/>
    <child link="torso_2"/>
    <limit effort="50000" lower="-0.3141592653589793" upper="0.7853981633974483" velocity="120.0"/>
    <dynamics damping="2.0" friction="0.0"/>
  </joint>
  <link name="chest">
    <inertial>
      <origin xyz="-0.010721 -0.00035277700000000003 0.07611099999999998" rpy="0 0 1.5707963267948966"/>
      <mass value="7.5231"/>
      <inertia ixx="0.04191694204925442" ixy="-0.00016439324174536638" ixz="-0.00012042228195009095" iyy="0.04519641209749711" iyz="0.0002913933054242345" izz="0.02862407719202973"/>
    </inertial>
    <visual>
      <origin xyz="0 -5.0000000000007924e-05 -0.06446999999999992" rpy="0 0 1.5707963267948966"/>
      <geometry>
        <mesh filename="package://ergoCub/meshes/simmechanics/sim_ecub_chest_prt.stl" scale="0.001 0.001 0.001"/>
      </geometry>
      <material name="chest_color">
        <color rgba="0.3 0.3 0.3 1"/>
      </material>
    </visual>
    <collision>
      <origin xyz="0 -5.0000000000007924e-05 -0.06446999999999992" rpy="0 0 1.5707963267948966"/>
      <geometry>
        <mesh filename="package://ergoCub/meshes/simmechanics/sim_ecub_chest_prt.stl" scale="0.001 0.001 0.001"/>
      </geometry>
    </collision>
  </link>
  <joint name="torso_yaw" type="revolute">
    <origin xyz="0 0 0.06446999999999994" rpy="0 0 0"/>
    <axis xyz="0.0 0.0 -1.0"/>
    <parent link="torso_2"/>
    <child link="chest"/>
    <limit effort="50000" lower="-0.7504915783575618" upper="0.7504915783575618" velocity="120.0"/>
    <dynamics damping="2.0" friction="0.0"/>
  </joint>
  <link name="r_shoulder_1">
    <inertial>
      <origin xyz="0.00032607653388369573 -0.0955420804432296 0.0003884043171779872" rpy="0.45734294556344546 -0.12149383150453615 1.2287112550496297"/>
      <mass value="0.78697"/>
      <inertia ixx="0.01" ixy="-0.0002037365870789176" ixz="0.00019328282679126072" iyy="0.01" iyz="4.943521163071587e-05" izz="0.01"/>
    </inertial>
    <visual>
      <origin xyz="-0.03736455866996381 0.0786663640924054 -0.16523200446151448" rpy="0.45734294556344546 -0.12149383150453615 1.2287112550496297"/>
      <geometry>
        <mesh filename="package://ergoCub/meshes/simmechanics/sim_ecub_r_shoulder_1_prt.stl" scale="0.001 0.001 0.001"/>
      </geometry>
      <material name="r_shoulder_1_color">
        <color rgba="0.9 0.9 0.9 1"/>
      </material>
    </visual>
    <collision>
      <origin xyz="-0.03736455866996381 0.0786663640924054 -0.16523200446151448" rpy="0.45734294556344546 -0.12149383150453615 1.2287112550496297"/>
      <geometry>
        <mesh filename="package://ergoCub/meshes/simmechanics/sim_ecub_r_shoulder_1_prt.stl" scale="0.001 0.001 0.001"/>
      </geometry>
    </collision>
  </link>
  <joint name="r_shoulder_pitch" type="revolute">
    <origin xyz="-0.0204593 -0.041145 0.11657900000000002" rpy="-0.27424832783738673 -0.38925923297765797 0.3681645553764718"/>
    <axis xyz="-3.4409606744501e-07 0.9999999783533522 4.2068387506866145e-07"/>
    <parent link="chest"/>
    <child link="r_shoulder_1"/>
    <limit effort="50000" lower="-3.0543261909900767" upper="0.3490658503988659" velocity="120.0"/>
    <dynamics damping="2.0" friction="0.0"/>
  </joint>
  <link name="r_shoulder_2">
    <inertial>
      <origin xyz="0.005113569084782336 -0.00021356072357139877 -0.020425582617945248" rpy="0.12008559189031787 -0.2297881760318691 1.288278055899408"/>
      <mass value="0.42492"/>
      <inertia ixx="0.01" ixy="4.861223258133038e-05" ixz="-6.295636746374883e-05" iyy="0.01" iyz="7.564891120081416e-05" izz="0.01"/>
    </inertial>
    <visual>
      <origin xyz="0.013901412308925503 0.19966640414374212 -0.1680465779300939" rpy="0.12008559189031787 -0.2297881760318691 1.288278055899408"/>
      <geometry>
        <mesh filename="package://ergoCub/meshes/simmechanics/sim_ecub_r_shoulder_2_prt.stl" scale="0.001 0.001 0.001"/>
      </geometry>
      <material name="r_shoulder_2_color">
        <color rgba="0.9 0.9 0.9 1"/>
      </material>
    </visual>
    <collision>
      <origin xyz="0.013901412308925503 0.19966640414374212 -0.1680465779300939" rpy="0.12008559189031787 -0.2297881760318691 1.288278055899408"/>
      <geometry>
        <mesh filename="package://ergoCub/meshes/simmechanics/sim_ecub_r_shoulder_2_prt.stl" scale="0.001 0.001 0.001"/>
      </geometry>
    </collision>
  </link>
  <joint name="r_shoulder_roll" type="revolute">
    <origin xyz="0.007047626988282561 -0.1210001256259653 -0.0025653969156163303" rpy="5.46356877807044e-07 0.3490654496846719 1.404737718226305e-07"/>
    <axis xyz="-0.9999998262417322 1.7128582631247002e-07 2.9287109011566503e-07"/>
    <parent link="r_shoulder_1"/>
    <child link="r_shoulder_2"/>
    <limit effort="50000" lower="0.20943951023931956" upper="2.8448866807507573" velocity="120.0"/>
    <dynamics damping="2.0" friction="0.0"/>
  </joint>
  <link name="r_shoulder_3">
    <inertial>
      <origin xyz="-8.316742504336366e-05 -3.0846217982133384e-05 -0.007966675096942738" rpy="0.12008559189031787 -0.2297881760318691 1.288278055899408"/>
      <mass value="0.2625"/>
      <inertia ixx="0.01" ixy="1.670395648073792e-06" ixz="1.0781350150663436e-05" iyy="0.01" iyz="5.495378795134566e-06" izz="0.01"/>
    </inertial>
    <visual>
      <origin xyz="0.02075132285211596 0.1996660773505882 -0.11374685915473098" rpy="0.12008559189031787 -0.2297881760318691 1.288278055899408"/>
      <geometry>
        <mesh filename="package://ergoCub/meshes/simmechanics/sim_ecub_r_shoulder_3_prt.stl" scale="0.001 0.001 0.001"/>
      </geometry>
      <material name="r_shoulder_3_color">
        <color rgba="0.9 0.9 0.9 1"/>
      </material>
    </visual>
    <collision>
      <origin xyz="0.02075132285211596 0.1996660773505882 -0.11374685915473098" rpy="0.12008559189031787 -0.2297881760318691 1.288278055899408"/>
      <geometry>
        <mesh filename="package://ergoCub/meshes/simmechanics/sim_ecub_r_shoulder_3_prt.stl" scale="0.001 0.001 0.001"/>
      </geometry>
    </collision>
  </link>
  <joint name="r_arm_ft_sensor" type="fixed">
    <origin xyz="-0.0068499105431904395 3.267931539541191e-07 -0.05429971877536288" rpy="0 0 0"/>
    <parent link="r_shoulder_2"/>
    <child link="r_shoulder_3"/>
    <dynamics damping="0.1"/>
  </joint>
  <link name="r_upperarm">
    <inertial>
      <origin xyz="0.0001470636560164315 -0.002335316124503578 -0.05011665894829496" rpy="0.12008559189031787 -0.2297881760318691 1.288278055899408"/>
      <mass value="1.77224"/>
      <inertia ixx="0.0033762" ixy="-7.67717e-05" ixz="-0.000513353" iyy="0.00337535" iyz="-0.000252914" izz="0.00175772"/>
    </inertial>
    <visual>
      <origin xyz="0.020751359543703298 0.19966616827789088 -0.09124663357473956" rpy="0.12008559189031787 -0.2297881760318691 1.288278055899408"/>
      <geometry>
        <mesh filename="package://ergoCub/meshes/simmechanics/sim_ecub_r_upperarm_prt.stl" scale="0.001 0.001 0.001"/>
      </geometry>
      <material name="green">
        <color rgba="0 1 0 1"/>
      </material>
    </visual>
    <collision>
      <origin xyz="0.020751359543703298 0.19966616827789088 -0.09124663357473956" rpy="0.12008559189031787 -0.2297881760318691 1.288278055899408"/>
      <geometry>
        <mesh filename="package://ergoCub/meshes/simmechanics/sim_ecub_r_upperarm_prt.stl" scale="0.001 0.001 0.001"/>
      </geometry>
    </collision>
  </link>
  <joint name="r_shoulder_yaw" type="revolute">
    <origin xyz="0 0 -0.022500225579988875" rpy="0 0 0"/>
    <axis xyz="1.7133815359560156e-07 -2.3659291614741562e-07 0.999999570574365"/>
    <parent link="r_shoulder_3"/>
    <child link="r_upperarm"/>
    <limit effort="50000" lower="-0.8726646259971648" upper="1.3962634015954636" velocity="120.0"/>
    <dynamics damping="2.0" friction="0.0"/>
  </joint>
  <link name="r_forearm">
    <inertial>
      <origin xyz="-0.018307104773072014 -0.0022154020139300568 -0.0881495480457185" rpy="0.12008559189031787 -0.2297881760318691 1.288278055899408"/>
      <mass value="0.8686"/>
      <inertia ixx="0.0023285790958423383" ixy="-1.90645127670097e-05" ixz="-0.0003325585747288408" iyy="0.0023564247616982936" iyz="-0.00013284359820333726" izz="0.0009819010250191388"/>
    </inertial>
    <visual>
      <origin xyz="0.010751314930868037 0.1981660958284493 0.03245299731653594" rpy="0.12008559189031787 -0.2297881760318691 1.288278055899408"/>
      <geometry>
        <mesh filename="package://ergoCub/meshes/simmechanics/sim_ecub_r_forearm_prt.stl" scale="0.001 0.001 0.001"/>
      </geometry>
      <material name="r_forearm_color">
        <color rgba="0.3 0.3 0.3 1"/>
      </material>
    </visual>
    <collision>
      <origin xyz="0.010751314930868037 0.1981660958284493 0.03245299731653594" rpy="0.12008559189031787 -0.2297881760318691 1.288278055899408"/>
      <geometry>
        <mesh filename="package://ergoCub/meshes/simmechanics/sim_ecub_r_forearm_prt.stl" scale="0.001 0.001 0.001"/>
      </geometry>
    </collision>
  </link>
  <joint name="r_elbow" type="revolute">
    <origin xyz="0.010000044612835839 0.001500072449440032 -0.1236996308912752" rpy="0 0 0"/>
    <axis xyz="3.352246002574083e-07 -0.9999999783534191 2.2068612626213735e-07"/>
    <parent link="r_upperarm"/>
    <child link="r_forearm"/>
    <limit effort="50000" lower="-0.05235987755982989" upper="1.3089969389957472" velocity="120.0"/>
    <dynamics damping="2.0" friction="0.0"/>
  </joint>
  <link name="r_wrist_1">
    <inertial>
      <origin xyz="0.0004027631276975266 -0.0010588265415277243 0.019141104288361327" rpy="0.12008559189031787 -0.2297881760318691 1.288278055899408"/>
      <mass value="0.033183"/>
      <inertia ixx="0.01" ixy="5.996854882610425e-07" ixz="-9.909270990847593e-07" iyy="0.01" iyz="-9.197047640270592e-08" izz="0.01"/>
    </inertial>
    <visual>
      <origin xyz="0.025751515213232625 0.20016678947605648 0.22680306204167913" rpy="0.12008559189031787 -0.2297881760318691 1.288278055899408"/>
      <geometry>
        <mesh filename="package://ergoCub/meshes/simmechanics/sim_ecub_r_wrist_1_prt.stl" scale="0.001 0.001 0.001"/>
      </geometry>
      <material name="r_wrist_1_color">
        <color rgba="0.9 0.9 0.9 1"/>
      </material>
    </visual>
    <collision>
      <origin xyz="0.025751515213232625 0.20016678947605648 0.22680306204167913" rpy="0.12008559189031787 -0.2297881760318691 1.288278055899408"/>
      <geometry>
        <mesh filename="package://ergoCub/meshes/simmechanics/sim_ecub_r_wrist_1_prt.stl" scale="0.001 0.001 0.001"/>
      </geometry>
    </collision>
  </link>
  <joint name="r_wrist_yaw" type="revolute">
    <origin xyz="-0.01500020028236461 -0.0020006936476072434 -0.19435006472514324" rpy="0 0 0"/>
    <axis xyz="-1.7133815359560156e-07 2.3659291614741562e-07 -0.999999570574365"/>
    <parent link="r_forearm"/>
    <child link="r_wrist_1"/>
    <limit effort="50000" lower="-0.2617993877991494" upper="0.6108652381980153" velocity="120.0"/>
    <dynamics damping="2.0" friction="0.0"/>
  </joint>
  <link name="r_wrist_2">
    <inertial>
      <origin xyz="0.003922717608066478 -0.004519500455993947 0.01227737513622662" rpy="0.12008559189031787 -0.2297881760318691 1.288278055899408"/>
      <mass value="0.0264562"/>
      <inertia ixx="6.56547e-05" ixy="-2.5348e-06" ixz="-1.51244e-05" iyy="6.49393e-05" iyz="-1.32416e-05" izz="1.33728e-05"/>
    </inertial>
    <visual>
      <origin xyz="0.025751515213232542 0.2001667894760563 0.22680306204167924" rpy="0.12008559189031787 -0.2297881760318691 1.288278055899408"/>
      <geometry>
        <mesh filename="package://ergoCub/meshes/simmechanics/sim_ecub_r_wrist_2_prt.stl" scale="0.001 0.001 0.001"/>
      </geometry>
      <material name="black">
        <color rgba="0 0 0 1"/>
      </material>
    </visual>
    <collision>
      <origin xyz="0.025751515213232542 0.2001667894760563 0.22680306204167924" rpy="0.12008559189031787 -0.2297881760318691 1.288278055899408"/>
      <geometry>
        <mesh filename="package://ergoCub/meshes/simmechanics/sim_ecub_r_wrist_2_prt.stl" scale="0.001 0.001 0.001"/>
      </geometry>
    </collision>
  </link>
  <joint name="r_wrist_roll" type="continuous">
    <origin xyz="0 0 0" rpy="0 0 0"/>
    <axis xyz="-0.9999998262417322 1.7128582631247002e-07 2.9287109011566503e-07"/>
    <parent link="r_wrist_1"/>
    <child link="r_wrist_2"/>
    <dynamics damping="0.1"/>
  </joint>
  <link name="r_hand_palm">
    <inertial>
      <origin xyz="-0.003867977118642306 -0.002792498733926896 -0.059703516091773656" rpy="0.12008559189031787 -0.2297881760318691 1.288278055899408"/>
      <mass value="0.189135"/>
      <inertia ixx="0.00019863" ixy="1.47038e-05" ixz="-2.03215e-05" iyy="0.000142173" iyz="5.53109e-06" izz="0.000108401"/>
    </inertial>
    <visual>
      <origin xyz="0.02575151521323255 0.20016678947605657 0.22680306204167927" rpy="0.12008559189031787 -0.2297881760318691 1.288278055899408"/>
      <geometry>
        <mesh filename="package://ergoCub/meshes/simmechanics/sim_ecub_r_hand_palm_prt.stl" scale="0.001 0.001 0.001"/>
      </geometry>
      <material name="red">
        <color rgba="1 0 0 1"/>
      </material>
    </visual>
    <collision>
      <origin xyz="0.02575151521323255 0.20016678947605657 0.22680306204167927" rpy="0.12008559189031787 -0.2297881760318691 1.288278055899408"/>
      <geometry>
        <mesh filename="package://ergoCub/meshes/simmechanics/sim_ecub_r_hand_palm_prt.stl" scale="0.001 0.001 0.001"/>
      </geometry>
    </collision>
  </link>
  <joint name="r_wrist_pitch" type="revolute">
    <origin xyz="0 0 0" rpy="0 0 0"/>
    <axis xyz="-3.352246002574083e-07 0.9999999783534191 -2.2068612626213735e-07"/>
    <parent link="r_wrist_2"/>
    <child link="r_hand_palm"/>
    <limit effort="50000" lower="-1.2217304763960306" upper="0.4363323129985824" velocity="120.0"/>
    <dynamics damping="2.0" friction="0.0"/>
  </joint>
  <link name="r_hand_pinkie_1">
    <inertial>
      <origin xyz="0.00012066652469319705 0.0037052461258312297 -0.011966578146940299" rpy="0.03293841693450851 -0.2510502277214382 -1.8063707999903837"/>
      <mass value="0.00283627"/>
      <inertia ixx="3.03645e-07" ixy="-3.01698e-10" ixz="-3.25911e-08" iyy="3.00808e-07" iyz="-5.31232e-09" izz="1.56809e-07"/>
    </inertial>
    <visual>
      <origin xyz="-0.028527203126593167 -0.19932629907859578 0.32260234794349524" rpy="0.03293841693450851 -0.2510502277214382 -1.8063707999903837"/>
      <geometry>
        <mesh filename="package://ergoCub/meshes/simmechanics/sim_ecub_r_hand_pinkie_1_prt.stl" scale="0.001 0.001 0.001"/>
      </geometry>
      <material name="blue">
        <color rgba="0 0 1 1"/>
      </material>
    </visual>
    <collision>
      <origin xyz="-0.028527203126593167 -0.19932629907859578 0.32260234794349524" rpy="0.03293841693450851 -0.2510502277214382 -1.8063707999903837"/>
      <geometry>
        <mesh filename="package://ergoCub/meshes/simmechanics/sim_ecub_r_hand_pinkie_1_prt.stl" scale="0.001 0.001 0.001"/>
      </geometry>
    </collision>
  </link>
  <joint name="r_pinkie_prox" type="continuous">
    <origin xyz="-0.03598229511630489 0.0023886829394013653 -0.09208533059471607" rpy="0 -0.08726707208822813 3.1154130190543565"/>
    <axis xyz="-1.0000005135466863 1.979209419246744e-07 4.060128685548503e-07"/>
    <parent link="r_hand_palm"/>
    <child link="r_hand_pinkie_1"/>
    <dynamics damping="0.1"/>
  </joint>
  <link name="r_hand_pinkie_2">
    <inertial>
      <origin xyz="1.7197070087928562e-05 0.0017846869131176724 -0.005611909589696484" rpy="0.03293841693450851 -0.2510502277214382 -1.8063707999903837"/>
      <mass value="0.00857923"/>
      <inertia ixx="2.55823e-06" ixy="-3.59629e-08" ixz="-7.27668e-07" iyy="2.79112e-06" iyz="-1.08559e-07" izz="5.1683e-07"/>
    </inertial>
    <visual>
      <origin xyz="-0.028527291616398644 -0.19782654821837128 0.34760258035440544" rpy="0.03293841693450851 -0.2510502277214382 -1.8063707999903837"/>
      <geometry>
        <mesh filename="package://ergoCub/meshes/simmechanics/sim_ecub_r_hand_pinkie_2_prt.stl" scale="0.001 0.001 0.001"/>
      </geometry>
      <material name="yellow">
        <color rgba="1 1 0 1"/>
      </material>
    </visual>
    <collision>
      <origin xyz="-0.028527291616398644 -0.19782654821837128 0.34760258035440544" rpy="0.03293841693450851 -0.2510502277214382 -1.8063707999903837"/>
      <geometry>
        <mesh filename="package://ergoCub/meshes/simmechanics/sim_ecub_r_hand_pinkie_2_prt.stl" scale="0.001 0.001 0.001"/>
      </geometry>
    </collision>
  </link>
  <joint name="r_pinkie_dist" type="continuous">
    <origin xyz="0 -0.0014997508602253018 -0.025000232410908096" rpy="0 0 0"/>
    <axis xyz="-1.0000005135466863 1.979209419246744e-07 4.060128685548503e-07"/>
    <parent link="r_hand_pinkie_1"/>
    <child link="r_hand_pinkie_2"/>
    <dynamics damping="0.1"/>
  </joint>
  <link name="r_hand_ring_1">
    <inertial>
      <origin xyz="0.0001425535059396731 0.0036420567912524016 -0.014331791473058686" rpy="0.03293841693450851 -0.2510502277214382 -1.8063707999903837"/>
      <mass value="0.00345703"/>
      <inertia ixx="4.42024e-07" ixy="-1.91202e-09" ixz="-5.67574e-08" iyy="4.46923e-07" iyz="-1.09909e-08" izz="1.93456e-07"/>
    </inertial>
    <visual>
      <origin xyz="-0.007527237008806751 -0.1993263860452736 0.326602384893858" rpy="0.03293841693450851 -0.2510502277214382 -1.8063707999903837"/>
      <geometry>
        <mesh filename="package://ergoCub/meshes/simmechanics/sim_ecub_r_hand_ring_1_prt.stl" scale="0.001 0.001 0.001"/>
      </geometry>
      <material name="pink">
        <color rgba="1 0 1 1"/>
      </material>
    </visual>
    <collision>
      <origin xyz="-0.007527237008806751 -0.1993263860452736 0.326602384893858" rpy="0.03293841693450851 -0.2510502277214382 -1.8063707999903837"/>
      <geometry>
        <mesh filename="package://ergoCub/meshes/simmechanics/sim_ecub_r_hand_ring_1_prt.stl" scale="0.001 0.001 0.001"/>
      </geometry>
    </collision>
  </link>
  <joint name="r_ring_prox" type="continuous">
    <origin xyz="-0.01541792137789915 0.0018501048853160618 -0.09790042637955282" rpy="0 -0.08726707208822813 3.1154130190543565"/>
    <axis xyz="-1.0000005135466863 1.979209419246744e-07 4.060128685548503e-07"/>
    <parent link="r_hand_palm"/>
    <child link="r_hand_ring_1"/>
    <dynamics damping="0.1"/>
  </joint>
  <link name="r_hand_ring_2">
    <inertial>
      <origin xyz="5.12901968831303e-05 0.001669633724482783 -0.003593808335425386" rpy="0.03293841693450851 -0.2510502277214382 -1.8063707999903837"/>
      <mass value="0.0091955"/>
      <inertia ixx="3.15753e-06" ixy="-5.0923e-08" ixz="-9.41261e-07" iyy="3.4723e-06" iyz="-1.45057e-07" izz="6.05547e-07"/>
    </inertial>
    <visual>
      <origin xyz="-0.007527194888446732 -0.19782646544374516 0.3566029490051788" rpy="0.03293841693450851 -0.2510502277214382 -1.8063707999903837"/>
      <geometry>
        <mesh filename="package://ergoCub/meshes/simmechanics/sim_ecub_r_hand_ring_2_prt.stl" scale="0.001 0.001 0.001"/>
      </geometry>
      <material name="cyan">
        <color rgba="0 1 1 1"/>
      </material>
    </visual>
    <collision>
      <origin xyz="-0.007527194888446732 -0.19782646544374516 0.3566029490051788" rpy="0.03293841693450851 -0.2510502277214382 -1.8063707999903837"/>
      <geometry>
        <mesh filename="package://ergoCub/meshes/simmechanics/sim_ecub_r_hand_ring_2_prt.stl" scale="0.001 0.001 0.001"/>
      </geometry>
    </collision>
  </link>
  <joint name="r_ring_dist" type="continuous">
    <origin xyz="0 -0.0014999206015293143 -0.03000056411131863" rpy="0 0 0"/>
    <axis xyz="-1.0000005135466863 1.979209419246744e-07 4.060128685548503e-07"/>
    <parent link="r_hand_ring_1"/>
    <child link="r_hand_ring_2"/>
    <dynamics damping="0.1"/>
  </joint>
  <link name="r_hand_thumb_1">
    <inertial>
      <origin xyz="0.020758108203487696 -0.0027448049867991042 -0.008805475830796439" rpy="0.3407559733652856 -0.16157290397540885 0.8505098820311924"/>
      <mass value="0.0346205"/>
      <inertia ixx="9.43988e-06" ixy="2.20083e-06" ixz="5.98173e-07" iyy="5.10002e-06" iyz="-2.49938e-06" izz="8.07407e-06"/>
    </inertial>
    <visual>
      <origin xyz="0.13221525745257978 0.1585157815675608 0.2540941242362456" rpy="0.3407559733652856 -0.16157290397540885 0.8505098820311924"/>
      <geometry>
        <mesh filename="package://ergoCub/meshes/simmechanics/sim_ecub_r_hand_thumb_1_prt.stl" scale="0.001 0.001 0.001"/>
      </geometry>
      <material name="green">
        <color rgba="0 1 0 1"/>
      </material>
    </visual>
    <collision>
      <origin xyz="0.13221525745257978 0.1585157815675608 0.2540941242362456" rpy="0.3407559733652856 -0.16157290397540885 0.8505098820311924"/>
      <geometry>
        <mesh filename="package://ergoCub/meshes/simmechanics/sim_ecub_r_hand_thumb_1_prt.stl" scale="0.001 0.001 0.001"/>
      </geometry>
    </collision>
  </link>
  <joint name="r_thumb_add" type="continuous">
    <origin xyz="0.023374917753110406 0.0030000775355234766 -0.03452353585390949" rpy="-0.08853690416789765 -0.20917986809225603 0.403968951543933"/>
    <axis xyz="9.579078125154794e-08 6.90101361611184e-08 1.0000003967894142"/>
    <parent link="r_hand_palm"/>
    <child link="r_hand_thumb_1"/>
    <dynamics damping="0.1"/>
  </joint>
  <link name="r_hand_thumb_2">
    <inertial>
      <origin xyz="0.009791876945086153 0.0043394430677464735 0.00026267613914743304" rpy="-1.3050072033505575 0.9949590577630557 0.6894456200851217"/>
      <mass value="0.00246082"/>
      <inertia ixx="1.79984e-07" ixy="1.42363e-08" ixz="1.51571e-08" iyy="1.63931e-07" iyz="-2.56683e-08" izz="1.8692e-07"/>
    </inertial>
    <visual>
      <origin xyz="-0.09219422223628063 0.23947631886662918 -0.219814684337369" rpy="-1.3050072033505575 0.9949590577630557 0.6894456200851217"/>
      <geometry>
        <mesh filename="package://ergoCub/meshes/simmechanics/sim_ecub_r_hand_thumb_2_prt.stl" scale="0.001 0.001 0.001"/>
      </geometry>
      <material name="white">
        <color rgba="1 1 1 1"/>
      </material>
    </visual>
    <collision>
      <origin xyz="-0.09219422223628063 0.23947631886662918 -0.219814684337369" rpy="-1.3050072033505575 0.9949590577630557 0.6894456200851217"/>
      <geometry>
        <mesh filename="package://ergoCub/meshes/simmechanics/sim_ecub_r_hand_thumb_2_prt.stl" scale="0.001 0.001 0.001"/>
      </geometry>
    </collision>
  </link>
  <joint name="r_thumb_prox" type="continuous">
    <origin xyz="0.0345419043814173 -0.0031447987794122334 -0.026071809138455138" rpy="1.7929080217310676 0.6514101167838809 -1.1138050653581883e-07"/>
    <axis xyz="-2.036798052024169e-07 -1.5008516943137984e-07 1.000000226690442"/>
    <parent link="r_hand_thumb_1"/>
    <child link="r_hand_thumb_2"/>
    <dynamics damping="0.1"/>
  </joint>
  <link name="r_hand_thumb_3">
    <inertial>
      <origin xyz="0.006464178605992202 0.001884904152624961 1.5404066026875052e-05" rpy="-1.3050072033505575 0.9949590577630557 0.6894456200851217"/>
      <mass value="0.00811336"/>
      <inertia ixx="1.82463e-06" ixy="6.72467e-07" ixz="3.3847e-07" iyy="9.46017e-07" iyz="-6.23617e-07" izz="1.87804e-06"/>
    </inertial>
    <visual>
      <origin xyz="-0.11219374098962248 0.2409758366164092 -0.2198142934019002" rpy="-1.3050072033505575 0.9949590577630557 0.6894456200851217"/>
      <geometry>
        <mesh filename="package://ergoCub/meshes/simmechanics/sim_ecub_r_hand_thumb_3_prt.stl" scale="0.001 0.001 0.001"/>
      </geometry>
      <material name="dblue">
        <color rgba="0 0 0.8 1"/>
      </material>
    </visual>
    <collision>
      <origin xyz="-0.11219374098962248 0.2409758366164092 -0.2198142934019002" rpy="-1.3050072033505575 0.9949590577630557 0.6894456200851217"/>
      <geometry>
        <mesh filename="package://ergoCub/meshes/simmechanics/sim_ecub_r_hand_thumb_3_prt.stl" scale="0.001 0.001 0.001"/>
      </geometry>
    </collision>
  </link>
  <joint name="r_thumb_dist" type="continuous">
    <origin xyz="0.019999518753341647 -0.0014995177497797718 -3.9093546871926677e-07" rpy="0 0 0"/>
    <axis xyz="-2.036798052024169e-07 -1.5008516943137984e-07 1.000000226690442"/>
    <parent link="r_hand_thumb_2"/>
    <child link="r_hand_thumb_3"/>
    <dynamics damping="0.1"/>
  </joint>
  <link name="r_hand_middle_1">
    <inertial>
      <origin xyz="0.00014288935851117235 0.003643274774255273 -0.014331647143315362" rpy="0.12008501986317731 -0.2297882840735942 -1.8533146530335884"/>
      <mass value="0.00345703"/>
      <inertia ixx="4.44131e-07" ixy="-5.70924e-09" ixz="-5.08723e-08" iyy="4.43007e-07" iyz="-3.26866e-08" izz="1.94758e-07"/>
    </inertial>
    <visual>
      <origin xyz="-0.016151209552035674 -0.19866593918881142 0.32980294282379513" rpy="0.12008501986317731 -0.2297882840735942 -1.8533146530335884"/>
      <geometry>
        <mesh filename="package://ergoCub/meshes/simmechanics/sim_ecub_r_hand_middle_1_prt.stl" scale="0.001 0.001 0.001"/>
      </geometry>
      <material name="dgreen">
        <color rgba="0.1 0.8 0.1 1"/>
      </material>
    </visual>
    <collision>
      <origin xyz="-0.016151209552035674 -0.19866593918881142 0.32980294282379513" rpy="0.12008501986317731 -0.2297882840735942 -1.8533146530335884"/>
      <geometry>
        <mesh filename="package://ergoCub/meshes/simmechanics/sim_ecub_r_hand_middle_1_prt.stl" scale="0.001 0.001 0.001"/>
      </geometry>
    </collision>
  </link>
  <joint name="r_middle_prox" type="continuous">
    <origin xyz="0.009600156192095595 0.0015008642793521432 -0.10299988189076881" rpy="0 -5.650294234014884e-07 -3.141592467955196"/>
    <axis xyz="-0.9999998262416893 3.56920377206707e-07 2.721582535170075e-07"/>
    <parent link="r_hand_palm"/>
    <child link="r_hand_middle_1"/>
    <dynamics damping="0.1"/>
  </joint>
  <link name="r_hand_middle_2">
    <inertial>
      <origin xyz="5.143109505644991e-05 0.0015994843505621748 -0.0035910973065023666" rpy="0.11954926259843997 -0.22799029281164018 -1.8531928341958708"/>
      <mass value="0.00912524"/>
      <inertia ixx="3.20008e-06" ixy="-1.25412e-07" ixz="-8.73252e-07" iyy="3.41534e-06" iyz="-4.04969e-07" izz="6.05895e-07"/>
    </inertial>
    <visual>
      <origin xyz="-0.016151302128169516 -0.19783968727776596 0.35943338575842404" rpy="0.11954926259843997 -0.22799029281164018 -1.8531928341958708"/>
      <geometry>
        <mesh filename="package://ergoCub/meshes/simmechanics/sim_ecub_r_hand_middle_2_prt.stl" scale="0.001 0.001 0.001"/>
      </geometry>
      <material name="gray">
        <color rgba="0.5 0.5 0.5 1"/>
      </material>
    </visual>
    <collision>
      <origin xyz="-0.016151302128169516 -0.19783968727776596 0.35943338575842404" rpy="0.11954926259843997 -0.22799029281164018 -1.8531928341958708"/>
      <geometry>
        <mesh filename="package://ergoCub/meshes/simmechanics/sim_ecub_r_hand_middle_2_prt.stl" scale="0.001 0.001 0.001"/>
      </geometry>
    </collision>
  </link>
  <joint name="r_middle_dist" type="continuous">
    <origin xyz="1.3550151000546462e-07 -0.0014995238274964628 -0.03000020325318492" rpy="-0.0018721728628663644 0 -2.576685250299645e-07"/>
    <axis xyz="-0.9999998262417538 9.878318872787173e-08 2.5044776373606137e-07"/>
    <parent link="r_hand_middle_1"/>
    <child link="r_hand_middle_2"/>
    <dynamics damping="0.1"/>
  </joint>
  <link name="r_hand_index_1">
    <inertial>
      <origin xyz="-0.008756982341443988 0.004177503042098157 -0.017783405308458122" rpy="0.20567444929844825 -0.20467244819585653 -1.8717733650332327"/>
      <mass value="0.0183891"/>
      <inertia ixx="2.45443e-06" ixy="-9.52402e-08" ixz="-6.61946e-08" iyy="2.15039e-06" iyz="-4.84755e-07" izz="1.19816e-06"/>
    </inertial>
    <visual>
      <origin xyz="-0.029013910407855184 -0.1986661648104223 0.293982522539359" rpy="0.20567444929844825 -0.20467244819585653 -1.8717733650332327"/>
      <geometry>
        <mesh filename="package://ergoCub/meshes/simmechanics/sim_ecub_r_hand_index_1_prt.stl" scale="0.001 0.001 0.001"/>
      </geometry>
      <material name="green">
        <color rgba="0 1 0 1"/>
      </material>
    </visual>
    <collision>
      <origin xyz="-0.029013910407855184 -0.1986661648104223 0.293982522539359" rpy="0.20567444929844825 -0.20467244819585653 -1.8717733650332327"/>
      <geometry>
        <mesh filename="package://ergoCub/meshes/simmechanics/sim_ecub_r_hand_index_1_prt.stl" scale="0.001 0.001 0.001"/>
      </geometry>
    </collision>
  </link>
  <joint name="r_index_add" type="continuous">
    <origin xyz="0.022470132804126554 0.0015006329961735065 -0.06858950116064205" rpy="0 0.08726600527288864 3.141592607344335"/>
    <axis xyz="-3.992524267790176e-07 0.999999978353397 2.1441989261905547e-07"/>
    <parent link="r_hand_palm"/>
    <child link="r_hand_index_1"/>
    <dynamics damping="0.1"/>
  </joint>
  <link name="r_hand_index_2">
    <inertial>
      <origin xyz="0.00014273208930988546 0.0036431776269647553 -0.014331302030487825" rpy="0.20567444929844825 -0.20467244819585653 -1.8717733650332327"/>
      <mass value="0.00345703"/>
      <inertia ixx="4.46661e-07" ixy="-8.54016e-09" ixz="-4.40204e-08" iyy="4.35924e-07" iyz="-5.37044e-08" izz="1.99939e-07"/>
    </inertial>
    <visual>
      <origin xyz="-0.019821360664818048 -0.19866600173088267 0.3246961457413715" rpy="0.20567444929844825 -0.20467244819585653 -1.8717733650332327"/>
      <geometry>
        <mesh filename="package://ergoCub/meshes/simmechanics/sim_ecub_r_hand_index_2_prt.stl" scale="0.001 0.001 0.001"/>
      </geometry>
      <material name="black">
        <color rgba="0 0 0 1"/>
      </material>
    </visual>
    <collision>
      <origin xyz="-0.019821360664818048 -0.19866600173088267 0.3246961457413715" rpy="0.20567444929844825 -0.20467244819585653 -1.8717733650332327"/>
      <geometry>
        <mesh filename="package://ergoCub/meshes/simmechanics/sim_ecub_r_hand_index_2_prt.stl" scale="0.001 0.001 0.001"/>
      </geometry>
    </collision>
  </link>
  <joint name="r_index_prox" type="continuous">
    <origin xyz="-0.009192549743036973 -1.630795395390905e-07 -0.03071362320201243" rpy="0 0 0"/>
    <axis xyz="-0.9999995872902697 -2.6872936789712476e-07 4.668360350512657e-07"/>
    <parent link="r_hand_index_1"/>
    <child link="r_hand_index_2"/>
    <dynamics damping="0.1"/>
  </joint>
  <link name="r_hand_index_3">
    <inertial>
      <origin xyz="4.5278546464917746e-05 0.0015998591566379616 -0.0035907529199530885" rpy="0.20567444929844825 -0.20467244819585653 -1.8717733650332327"/>
      <mass value="0.00912524"/>
      <inertia ixx="3.24051e-06" ixy="-1.86597e-07" ixz="-7.96957e-07" iyy="3.3218e-06" iyz="-6.51325e-07" izz="6.59072e-07"/>
    </inertial>
    <visual>
      <origin xyz="-0.01982140194297418 -0.19716617877473372 0.3546966306597608" rpy="0.20567444929844825 -0.20467244819585653 -1.8717733650332327"/>
      <geometry>
        <mesh filename="package://ergoCub/meshes/simmechanics/sim_ecub_r_hand_index_3_prt.stl" scale="0.001 0.001 0.001"/>
      </geometry>
      <material name="red">
        <color rgba="1 0 0 1"/>
      </material>
    </visual>
    <collision>
      <origin xyz="-0.01982140194297418 -0.19716617877473372 0.3546966306597608" rpy="0.20567444929844825 -0.20467244819585653 -1.8717733650332327"/>
      <geometry>
        <mesh filename="package://ergoCub/meshes/simmechanics/sim_ecub_r_hand_index_3_prt.stl" scale="0.001 0.001 0.001"/>
      </geometry>
    </collision>
  </link>
  <joint name="r_index_dist" type="continuous">
    <origin xyz="0 -0.0014998229561488108 -0.030000484918389303" rpy="0 0 0"/>
    <axis xyz="-0.9999995872902697 -2.6872936789712476e-07 4.668360350512657e-07"/>
    <parent link="r_hand_index_2"/>
    <child link="r_hand_index_3"/>
    <dynamics damping="0.1"/>
  </joint>
  <link name="neck_2">
    <inertial>
      <origin xyz="-0.0063057700000000005 3.0141299999999995e-05 0.0063730000000000175" rpy="0 0 1.5707963267948966"/>
      <mass value="0.1214"/>
      <inertia ixx="3.861578060048098e-05" ixy="9.40651099559515e-08" ixz="4.885917836747849e-08" iyy="4.554012445972414e-05" iyz="-8.650960207598158e-06" izz="3.7658650611968296e-05"/>
    </inertial>
    <visual>
      <origin xyz="-0.00486150999999799 -4.999999999995535e-05 -0.28977" rpy="0 0 1.5707963267948966"/>
      <geometry>
        <mesh filename="package://ergoCub/meshes/simmechanics/sim_ecub_head_neck_2_prt.stl" scale="0.001 0.001 0.001"/>
      </geometry>
      <material name="neck_2_color">
        <color rgba="0.9 0.9 0.9 1"/>
      </material>
    </visual>
    <collision>
      <origin xyz="-0.00486150999999799 -4.999999999995535e-05 -0.28977" rpy="0 0 1.5707963267948966"/>
      <geometry>
        <mesh filename="package://ergoCub/meshes/simmechanics/sim_ecub_head_neck_2_prt.stl" scale="0.001 0.001 0.001"/>
      </geometry>
    </collision>
  </link>
  <joint name="SIM_ECUB_CHEST--SIM_ECUB_HEAD_NECK_2" type="continuous">
    <origin xyz="0.00486151 0 0.22529999999999997" rpy="0 0 0"/>
    <axis xyz="0.0 -1.0 0.0"/>
    <parent link="chest"/>
    <child link="neck_2"/>
    <dynamics damping="0.1"/>
  </joint>
  <link name="neck_3">
    <inertial>
      <origin xyz="0.0007590499999999998 -4.091691e-05 0.03603500000000004" rpy="0 0 1.5707963267948966"/>
      <mass value="0.18386"/>
      <inertia ixx="0.00011106913706951727" ixy="-1.8198231862739594e-07" ixz="-2.5847486677071986e-07" iyy="0.00010018591415610227" iyz="-6.328519130444547e-06" izz="3.74339884905173e-05"/>
    </inertial>
    <visual>
      <origin xyz="-0.0048615099999979915 -4.9999999999924684e-05 -0.29927000000000026" rpy="0 0 1.5707963267948966"/>
      <geometry>
        <mesh filename="package://ergoCub/meshes/simmechanics/sim_ecub_head_neck_3_prt.stl" scale="0.001 0.001 0.001"/>
      </geometry>
      <material name="neck_3_color">
        <color rgba="0.9 0.9 0.9 1"/>
      </material>
    </visual>
    <collision>
      <origin xyz="-0.0048615099999979915 -4.9999999999924684e-05 -0.29927000000000026" rpy="0 0 1.5707963267948966"/>
      <geometry>
        <mesh filename="package://ergoCub/meshes/simmechanics/sim_ecub_head_neck_3_prt.stl" scale="0.001 0.001 0.001"/>
      </geometry>
    </collision>
  </link>
  <joint name="neck_roll" type="revolute">
    <origin xyz="0 0 0.009500000000000008" rpy="0 0 0"/>
    <axis xyz="1.0 0.0 0.0"/>
    <parent link="neck_2"/>
    <child link="neck_3"/>
    <limit effort="50000" lower="-0.3490658503988659" upper="0.3490658503988659" velocity="120.0"/>
    <dynamics damping="2.0" friction="0.0"/>
  </joint>
  <link name="head">
    <inertial>
      <origin xyz="-0.02038851 0.003984110000000001 0.034331999999999974" rpy="0 0 1.5707963267948966"/>
      <mass value="1.8728"/>
      <inertia ixx="0.009865805073016778" ixy="-0.0002477428885065946" ixz="0.00012256091302229524" iyy="0.008488011210133962" iyz="0.00016698008924991272" izz="0.008275080165392593"/>
    </inertial>
    <visual>
      <origin xyz="-0.004861509999998024 -4.999999999993563e-05 -0.3684200000000006" rpy="0 0 1.5707963267948966"/>
      <geometry>
        <mesh filename="package://ergoCub/meshes/simmechanics/sim_ecub_head_prt.stl" scale="0.001 0.001 0.001"/>
      </geometry>
      <material name="head_color">
        <color rgba="0.9 0.9 0.9 1"/>
      </material>
    </visual>
    <collision>
      <origin xyz="-0.004861509999998024 -4.999999999993563e-05 -0.3684200000000006" rpy="0 0 1.5707963267948966"/>
      <geometry>
        <mesh filename="package://ergoCub/meshes/simmechanics/sim_ecub_head_prt.stl" scale="0.001 0.001 0.001"/>
      </geometry>
    </collision>
  </link>
  <joint name="SIM_ECUB_HEAD_NECK_3--SIM_ECUB_HEAD" type="continuous">
    <origin xyz="0 0 0.06915000000000004" rpy="0 0 0"/>
    <axis xyz="0.0 0.0 -1.0"/>
    <parent link="neck_3"/>
    <child link="head"/>
    <dynamics damping="0.1"/>
  </joint>
  <link name="imu_frame"/>
  <joint name="imu_frame_fixed_joint" type="fixed">
    <origin xyz="-0.004299998 -0.0055 0.03823499999999996" rpy="3.141592653589793 0 1.5707963267948966"/>
    <parent link="head"/>
    <child link="imu_frame"/>
    <dynamics damping="0.1"/>
  </joint>
  <link name="head_laser_frame"/>
  <joint name="head_laser_frame_fixed_joint" type="fixed">
    <origin xyz="4.99999999999997e-05 0 0.13480199999999992" rpy="0 0 1.5707963267948966"/>
    <parent link="head"/>
    <child link="head_laser_frame"/>
    <dynamics damping="0.1"/>
  </joint>
  <link name="realsense">
    <inertial>
      <origin xyz="-0.015665513063136835 0.004519999999999997 0.0027449336073371855" rpy="-0.00025958199854238625 0 1.5707963267948972"/>
      <mass value="0.0973042"/>
      <inertia ixx="0.000187087" ixy="-4.78755e-05" ixz="-7.18346e-06" iyy="0.000133643" iyz="-2.55241e-05" izz="0.00029632"/>
    </inertial>
    <visual>
      <origin xyz="-0.0672560322839365 -1.999999999987034e-05 -0.44483047344204346" rpy="-0.00025958199854238625 0 1.5707963267948972"/>
      <geometry>
        <mesh filename="package://ergoCub/meshes/simmechanics/sim_ecub_realsense_prt.stl" scale="0.001 0.001 0.001"/>
      </geometry>
      <material name="blue">
        <color rgba="0 0 1 1"/>
      </material>
    </visual>
    <collision>
      <origin xyz="-0.0672560322839365 -1.999999999987034e-05 -0.44483047344204346" rpy="-0.00025958199854238625 0 1.5707963267948972"/>
      <geometry>
        <mesh filename="package://ergoCub/meshes/simmechanics/sim_ecub_realsense_prt.stl" scale="0.001 0.001 0.001"/>
      </geometry>
    </collision>
  </link>
  <joint name="camera-tilt" type="continuous">
    <origin xyz="0.06250999 -3e-05 0.07639299999999999" rpy="0 0.0002595819985423862 0"/>
    <axis xyz="-2.220446049250313e-16 1.0000000000000002 0.0"/>
    <parent link="head"/>
    <child link="realsense"/>
    <dynamics damping="0.1"/>
  </joint>
  <link name="realsense_depth_frame"/>
  <joint name="realsense_depth_frame_fixed_joint" type="fixed">
    <origin xyz="0.00751550026595621 0.010000000000000004 0" rpy="-1.5707962931078618 0 -1.5707963267948968"/>
    <parent link="realsense"/>
    <child link="realsense_depth_frame"/>
    <dynamics damping="0.1"/>
  </joint>
  <link name="realsense_rgb_frame"/>
  <joint name="realsense_rgb_frame_fixed_joint" type="fixed">
    <origin xyz="0.00751550026595621 -0.0115 0" rpy="-1.5707962931078618 0 -1.5707963267948968"/>
    <parent link="realsense"/>
    <child link="realsense_rgb_frame"/>
    <dynamics damping="0.1"/>
  </joint>
  <link name="l_shoulder_1">
    <inertial>
      <origin xyz="8.813465633825818e-05 0.09554178705277518 0.0004984818421107096" rpy="-0.054063667179708695 0.2748965159766948 1.8097197019610352"/>
      <mass value="0.78644"/>
      <inertia ixx="0.01" ixy="0.000203651982588129" ixz="-0.00019290749384412868" iyy="0.01" iyz="4.935516884946103e-05" izz="0.01"/>
    </inertial>
    <visual>
      <origin xyz="0.050280138935658414 -0.07875979528419856 -0.1617502817861287" rpy="-0.054063667179708695 0.2748965159766948 1.8097197019610352"/>
      <geometry>
        <mesh filename="package://ergoCub/meshes/simmechanics/sim_ecub_l_shoulder_1_prt.stl" scale="0.001 0.001 0.001"/>
      </geometry>
      <material name="l_shoulder_1_color">
        <color rgba="0.9 0.9 0.9 1"/>
      </material>
    </visual>
    <collision>
      <origin xyz="0.050280138935658414 -0.07875979528419856 -0.1617502817861287" rpy="-0.054063667179708695 0.2748965159766948 1.8097197019610352"/>
      <geometry>
        <mesh filename="package://ergoCub/meshes/simmechanics/sim_ecub_l_shoulder_1_prt.stl" scale="0.001 0.001 0.001"/>
      </geometry>
    </collision>
  </link>
  <joint name="l_shoulder_pitch" type="revolute">
    <origin xyz="-0.0204593 0.041145 0.11657900000000002" rpy="0.25504097964037203 0.11691445967672928 -0.23139612148175434"/>
    <axis xyz="4.453300185801312e-07 0.9999999783533606 2.834495320125363e-07"/>
    <parent link="chest"/>
    <child link="l_shoulder_1"/>
    <limit effort="50000" lower="-3.0543261909900767" upper="0.3490658503988659" velocity="120.0"/>
    <dynamics damping="2.0" friction="0.0"/>
  </joint>
  <link name="l_shoulder_2">
    <inertial>
      <origin xyz="0.00751909206430745 0.0001880431797245674 -0.020486312998951983" rpy="0.12008501986317731 0.2297882840735942 1.8533146530335884"/>
      <mass value="0.42492"/>
      <inertia ixx="0.01" ixy="-4.970295695717944e-05" ixz="6.330525777839263e-05" iyy="0.01" iyz="7.688616481869128e-05" izz="0.01"/>
    </inertial>
    <visual>
      <origin xyz="0.016428503132473918 -0.19975933535232596 -0.1680239607265381" rpy="0.12008501986317731 0.2297882840735942 1.8533146530335884"/>
      <geometry>
        <mesh filename="package://ergoCub/meshes/simmechanics/sim_ecub_l_shoulder_2_prt.stl" scale="0.001 0.001 0.001"/>
      </geometry>
      <material name="l_shoulder_2_color">
        <color rgba="0.9 0.9 0.9 1"/>
      </material>
    </visual>
    <collision>
      <origin xyz="0.016428503132473918 -0.19975933535232596 -0.1680239607265381" rpy="0.12008501986317731 0.2297882840735942 1.8533146530335884"/>
      <geometry>
        <mesh filename="package://ergoCub/meshes/simmechanics/sim_ecub_l_shoulder_2_prt.stl" scale="0.001 0.001 0.001"/>
      </geometry>
    </collision>
  </link>
  <joint name="l_shoulder_roll" type="revolute">
    <origin xyz="0.00492425107543696 0.12099955745141479 0.0008682398676788106" rpy="0 -0.17453283291838068 -3.434122541820032e-07"/>
    <axis xyz="0.9999998262416893 3.56920377206707e-07 2.721582535170075e-07"/>
    <parent link="l_shoulder_1"/>
    <child link="l_shoulder_2"/>
    <limit effort="50000" lower="0.20943951023931956" upper="2.8448866807507573" velocity="120.0"/>
    <dynamics damping="2.0" friction="0.0"/>
  </joint>
  <link name="l_shoulder_3">
    <inertial>
      <origin xyz="8.299949315321992e-05 3.1036481120683135e-05 -0.007966353749424893" rpy="0.12008501986317731 0.2297882840735942 1.8533146530335884"/>
      <mass value="0.2625"/>
      <inertia ixx="0.01" ixy="-1.0703025424915093e-06" ixz="-1.0788505742892297e-05" iyy="0.01" iyz="5.6102647292846985e-06" izz="0.01"/>
    </inertial>
    <visual>
      <origin xyz="0.020778568919260394 -0.1997595789508428 -0.11372408057794761" rpy="0.12008501986317731 0.2297882840735942 1.8533146530335884"/>
      <geometry>
        <mesh filename="package://ergoCub/meshes/simmechanics/sim_ecub_l_shoulder_3_prt.stl" scale="0.001 0.001 0.001"/>
      </geometry>
      <material name="l_shoulder_3_color">
        <color rgba="0.9 0.9 0.9 1"/>
      </material>
    </visual>
    <collision>
      <origin xyz="0.020778568919260394 -0.1997595789508428 -0.11372408057794761" rpy="0.12008501986317731 0.2297882840735942 1.8533146530335884"/>
      <geometry>
        <mesh filename="package://ergoCub/meshes/simmechanics/sim_ecub_l_shoulder_3_prt.stl" scale="0.001 0.001 0.001"/>
      </geometry>
    </collision>
  </link>
  <joint name="l_arm_ft_sensor" type="fixed">
    <origin xyz="-0.004350065786786487 2.435985168303123e-07 -0.054299880148590496" rpy="0 0 0"/>
    <parent link="l_shoulder_2"/>
    <child link="l_shoulder_3"/>
    <dynamics damping="0.1"/>
  </joint>
  <link name="l_upperarm">
    <inertial>
      <origin xyz="0.0001304503312096507 0.002253311458823959 -0.05006471572755228" rpy="0.12008501986317731 0.2297882840735942 1.8533146530335884"/>
      <mass value="1.77085"/>
      <inertia ixx="0.00337743" ixy="7.38594e-05" ixz="0.000509552" iyy="0.0033716" iyz="-0.00025332" izz="0.00175055"/>
    </inertial>
    <visual>
      <origin xyz="0.020778592897575863 -0.1997596710372755 -0.09122385499794639" rpy="0.12008501986317731 0.2297882840735942 1.8533146530335884"/>
      <geometry>
        <mesh filename="package://ergoCub/meshes/simmechanics/sim_ecub_l_upperarm_prt.stl" scale="0.001 0.001 0.001"/>
      </geometry>
      <material name="yellow">
        <color rgba="1 1 0 1"/>
      </material>
    </visual>
    <collision>
      <origin xyz="0.020778592897575863 -0.1997596710372755 -0.09122385499794639" rpy="0.12008501986317731 0.2297882840735942 1.8533146530335884"/>
      <geometry>
        <mesh filename="package://ergoCub/meshes/simmechanics/sim_ecub_l_upperarm_prt.stl" scale="0.001 0.001 0.001"/>
      </geometry>
    </collision>
  </link>
  <joint name="l_shoulder_yaw" type="revolute">
    <origin xyz="0 0 -0.022500225580001282" rpy="0 0 0"/>
    <axis xyz="3.936910710766739e-07 -1.8507626386998766e-07 -0.9999995705743131"/>
    <parent link="l_shoulder_3"/>
    <child link="l_upperarm"/>
    <limit effort="50000" lower="-0.8726646259971648" upper="1.3962634015954636" velocity="120.0"/>
    <dynamics damping="2.0" friction="0.0"/>
  </joint>
  <link name="l_forearm">
    <inertial>
      <origin xyz="-0.01855325167731582 0.0023120102330188297 -0.08919372867102593" rpy="0.12008501986317731 0.2297882840735942 1.8533146530335884"/>
      <mass value="0.87311"/>
      <inertia ixx="0.002293341831421822" ixy="2.3424540820979835e-05" ixz="0.00032535745129925705" iyy="0.002316179177445308" iyz="-0.00013852464521209215" izz="0.0009905788513129515"/>
    </inertial>
    <visual>
      <origin xyz="0.010778478112345367 -0.19825960681678684 0.03247577032026804" rpy="0.12008501986317731 0.2297882840735942 1.8533146530335884"/>
      <geometry>
        <mesh filename="package://ergoCub/meshes/simmechanics/sim_ecub_l_forearm_prt.stl" scale="0.001 0.001 0.001"/>
      </geometry>
      <material name="l_forearm_color">
        <color rgba="0.3 0.3 0.3 1"/>
      </material>
    </visual>
    <collision>
      <origin xyz="0.010778478112345367 -0.19825960681678684 0.03247577032026804" rpy="0.12008501986317731 0.2297882840735942 1.8533146530335884"/>
      <geometry>
        <mesh filename="package://ergoCub/meshes/simmechanics/sim_ecub_l_forearm_prt.stl" scale="0.001 0.001 0.001"/>
      </geometry>
    </collision>
  </link>
  <joint name="l_elbow" type="revolute">
    <origin xyz="0.010000114785230524 -0.0015000642204885117 -0.12369962531821438" rpy="0 0 0"/>
    <axis xyz="-1.4958988243767013e-07 -0.9999999783534517 -2.7220291587415346e-07"/>
    <parent link="l_upperarm"/>
    <child link="l_forearm"/>
    <limit effort="50000" lower="-0.05235987755982989" upper="1.3089969389957472" velocity="120.0"/>
    <dynamics damping="2.0" friction="0.0"/>
  </joint>
  <link name="l_wrist_1">
    <inertial>
      <origin xyz="-0.00040255429275967355 0.001058195920348587 0.019141145908370766" rpy="0.12008501986317731 0.2297882840735942 1.8533146530335884"/>
      <mass value="0.033183"/>
      <inertia ixx="0.01" ixy="-2.7693727497015517e-07" ixz="9.289596768802227e-07" iyy="0.01" iyz="-2.3804023191404694e-07" izz="0.01"/>
    </inertial>
  </link>
  <joint name="l_wrist_yaw" type="revolute">
    <origin xyz="-0.015000090840254901 0.002000700875326722 -0.1943500730975977" rpy="0 0 0"/>
    <axis xyz="-3.936910710766739e-07 1.8507626386998766e-07 0.9999995705743131"/>
    <parent link="l_forearm"/>
    <child link="l_wrist_1"/>
    <limit effort="50000" lower="-0.2617993877991494" upper="0.6108652381980153" velocity="120.0"/>
    <dynamics damping="2.0" friction="0.0"/>
  </joint>
  <link name="l_wrist_2">
    <inertial>
      <origin xyz="0.00010461925064075839 0.002335285871915199 -0.005394190274622179" rpy="0.12008501986317731 0.2297882840735942 1.8533146530335884"/>
      <mass value="0.00945549"/>
      <inertia ixx="6.61925e-07" ixy="-7.01216e-08" ixz="-4.03309e-08" iyy="4.52417e-07" iyz="3.49146e-08" izz="8.25803e-07"/>
    </inertial>
    <visual>
      <origin xyz="0.02577856895260044 -0.20026030769211364 0.22682584341786585" rpy="0.12008501986317731 0.2297882840735942 1.8533146530335884"/>
      <geometry>
        <mesh filename="package://ergoCub/meshes/simmechanics/sim_ecub_l_wrist_2_prt.stl" scale="0.001 0.001 0.001"/>
      </geometry>
      <material name="pink">
        <color rgba="1 0 1 1"/>
      </material>
    </visual>
    <collision>
      <origin xyz="0.02577856895260044 -0.20026030769211364 0.22682584341786585" rpy="0.12008501986317731 0.2297882840735942 1.8533146530335884"/>
      <geometry>
        <mesh filename="package://ergoCub/meshes/simmechanics/sim_ecub_l_wrist_2_prt.stl" scale="0.001 0.001 0.001"/>
      </geometry>
    </collision>
  </link>
  <joint name="l_wrist_roll" type="continuous">
    <origin xyz="0 0 0" rpy="0 0 0"/>
    <axis xyz="-0.9999998262416893 -3.56920377206707e-07 -2.721582535170075e-07"/>
    <parent link="l_wrist_1"/>
    <child link="l_wrist_2"/>
    <dynamics damping="0.1"/>
  </joint>
  <link name="l_hand_palm">
    <inertial>
      <origin xyz="-0.0034640807528164286 0.002659508810032102 -0.05915907043241406" rpy="0.12008501986317731 0.2297882840735942 1.8533146530335884"/>
      <mass value="0.193024"/>
      <inertia ixx="0.000203612" ixy="-1.66069e-05" ixz="2.22683e-05" iyy="0.000146966" iyz="6.67926e-06" izz="0.000112031"/>
    </inertial>
    <visual>
      <origin xyz="0.025778568952600084 -0.2002603076921139 0.22682584341786585" rpy="0.12008501986317731 0.2297882840735942 1.8533146530335884"/>
      <geometry>
        <mesh filename="package://ergoCub/meshes/simmechanics/sim_ecub_l_hand_palm_prt.stl" scale="0.001 0.001 0.001"/>
      </geometry>
      <material name="cyan">
        <color rgba="0 1 1 1"/>
      </material>
    </visual>
    <collision>
      <origin xyz="0.025778568952600084 -0.2002603076921139 0.22682584341786585" rpy="0.12008501986317731 0.2297882840735942 1.8533146530335884"/>
      <geometry>
        <mesh filename="package://ergoCub/meshes/simmechanics/sim_ecub_l_hand_palm_prt.stl" scale="0.001 0.001 0.001"/>
      </geometry>
    </collision>
  </link>
  <joint name="l_wrist_pitch" type="revolute">
    <origin xyz="0 0 0" rpy="0 0 0"/>
    <axis xyz="-1.4958988243767013e-07 -0.9999999783534517 -2.7220291587415346e-07"/>
    <parent link="l_wrist_2"/>
    <child link="l_hand_palm"/>
    <limit effort="50000" lower="-1.2217304763960306" upper="0.4363323129985824" velocity="120.0"/>
    <dynamics damping="2.0" friction="0.0"/>
  </joint>
  <link name="l_hand_index_1">
    <inertial>
      <origin xyz="0.008775274459774302 0.004269452512144972 -0.017750570367235263" rpy="0.20567444929844825 0.20467244819585653 1.8717733650332327"/>
      <mass value="0.0183891"/>
      <inertia ixx="2.4459e-06" ixy="9.87525e-08" ixz="6.73219e-08" iyy="2.15366e-06" iyz="-4.87291e-07" izz="1.21424e-06"/>
    </inertial>
    <visual>
      <origin xyz="0.02904319388181456 -0.19871027157305815 0.29400345867182476" rpy="0.20567444929844825 0.20467244819585653 1.8717733650332327"/>
      <geometry>
        <mesh filename="package://ergoCub/meshes/simmechanics/sim_ecub_l_hand_index_1_prt.stl" scale="0.001 0.001 0.001"/>
      </geometry>
      <material name="green">
        <color rgba="0 1 0 1"/>
      </material>
    </visual>
    <collision>
      <origin xyz="0.02904319388181456 -0.19871027157305815 0.29400345867182476" rpy="0.20567444929844825 0.20467244819585653 1.8717733650332327"/>
      <geometry>
        <mesh filename="package://ergoCub/meshes/simmechanics/sim_ecub_l_hand_index_1_prt.stl" scale="0.001 0.001 0.001"/>
      </geometry>
    </collision>
  </link>
  <joint name="l_index_add" type="continuous">
    <origin xyz="0.022469969224748417 -0.0015500298468021645 -0.06859012009285945" rpy="0 -0.08726657030232389 2.273729335436677e-07"/>
    <axis xyz="3.992524267790176e-07 0.999999978353397 2.1441989261905547e-07"/>
    <parent link="l_hand_palm"/>
    <child link="l_hand_index_1"/>
    <dynamics damping="0.1"/>
  </joint>
  <link name="l_hand_index_2">
    <inertial>
      <origin xyz="0.00014299124504029564 0.0036421271566798585 -0.014330898644831003" rpy="0.20567444929844825 0.20467244819585653 1.8717733650332327"/>
      <mass value="0.00345703"/>
      <inertia ixx="4.44502e-07" ixy="5.70823e-09" ixz="4.71528e-08" iyy="4.4049e-07" iyz="-4.56705e-08" izz="1.97519e-07"/>
    </inertial>
    <visual>
      <origin xyz="0.01985064413877765 -0.19871010849351883 0.32471708187383713" rpy="0.20567444929844825 0.20467244819585653 1.8717733650332327"/>
      <geometry>
        <mesh filename="package://ergoCub/meshes/simmechanics/sim_ecub_l_hand_index_2_prt.stl" scale="0.001 0.001 0.001"/>
      </geometry>
      <material name="white">
        <color rgba="1 1 1 1"/>
      </material>
    </visual>
    <collision>
      <origin xyz="0.01985064413877765 -0.19871010849351883 0.32471708187383713" rpy="0.20567444929844825 0.20467244819585653 1.8717733650332327"/>
      <geometry>
        <mesh filename="package://ergoCub/meshes/simmechanics/sim_ecub_l_hand_index_2_prt.stl" scale="0.001 0.001 0.001"/>
      </geometry>
    </collision>
  </link>
  <joint name="l_index_prox" type="continuous">
    <origin xyz="0.009192549743036973 -1.6307953948357934e-07 -0.030713623202012375" rpy="0 0 0"/>
    <axis xyz="-0.9999995872902697 2.6872936789712476e-07 -4.668360350512657e-07"/>
    <parent link="l_hand_index_1"/>
    <child link="l_hand_index_2"/>
    <dynamics damping="0.1"/>
  </joint>
  <link name="l_hand_index_3">
    <inertial>
      <origin xyz="5.9109449817802695e-05 0.0016001193440265127 -0.0035910331602220236" rpy="0.20567444929844825 0.20467244819585653 1.8717733650332327"/>
      <mass value="0.00912524"/>
      <inertia ixx="3.23928e-06" ixy="1.8521e-07" ixz="7.98775e-07" iyy="3.32445e-06" iyz="-6.45784e-07" izz="6.57272e-07"/>
    </inertial>
    <visual>
      <origin xyz="0.019850732699260007 -0.19720947570560096 0.35471630507241353" rpy="0.20567444929844825 0.20467244819585653 1.8717733650332327"/>
      <geometry>
        <mesh filename="package://ergoCub/meshes/simmechanics/sim_ecub_l_hand_index_3_prt.stl" scale="0.001 0.001 0.001"/>
      </geometry>
      <material name="dblue">
        <color rgba="0 0 0.8 1"/>
      </material>
    </visual>
    <collision>
      <origin xyz="0.019850732699260007 -0.19720947570560096 0.35471630507241353" rpy="0.20567444929844825 0.20467244819585653 1.8717733650332327"/>
      <geometry>
        <mesh filename="package://ergoCub/meshes/simmechanics/sim_ecub_l_hand_index_3_prt.stl" scale="0.001 0.001 0.001"/>
      </geometry>
    </collision>
  </link>
  <joint name="l_index_dist" type="continuous">
    <origin xyz="0 -0.0015006327879180659 -0.029999223198576064" rpy="0 0 0"/>
    <axis xyz="-0.9999995872902697 2.6872936789712476e-07 -4.668360350512657e-07"/>
    <parent link="l_hand_index_2"/>
    <child link="l_hand_index_3"/>
    <dynamics damping="0.1"/>
  </joint>
  <link name="l_hand_thumb_1">
    <inertial>
      <origin xyz="0.020687992873158395 0.003255220723100055 -0.008896940067464165" rpy="0.3407559733652857 0.16157290397540883 2.2910827715586013"/>
      <mass value="0.0346205"/>
      <inertia ixx="9.63708e-06" ixy="-2.06718e-06" ixz="-4.99381e-07" iyy="4.92086e-06" iyz="-2.5225e-06" izz="8.15032e-06"/>
    </inertial>
    <visual>
      <origin xyz="0.13228035835416185 -0.15858996430408165 0.25411021131850486" rpy="0.3407559733652857 0.16157290397540883 2.2910827715586013"/>
      <geometry>
        <mesh filename="package://ergoCub/meshes/simmechanics/sim_ecub_l_hand_thumb_1_prt.stl" scale="0.001 0.001 0.001"/>
      </geometry>
      <material name="dgreen">
        <color rgba="0.1 0.8 0.1 1"/>
      </material>
    </visual>
    <collision>
      <origin xyz="0.13228035835416185 -0.15858996430408165 0.25411021131850486" rpy="0.3407559733652857 0.16157290397540883 2.2910827715586013"/>
      <geometry>
        <mesh filename="package://ergoCub/meshes/simmechanics/sim_ecub_l_hand_thumb_1_prt.stl" scale="0.001 0.001 0.001"/>
      </geometry>
    </collision>
  </link>
  <joint name="l_thumb_add" type="continuous">
    <origin xyz="0.02337493781683802 -0.003000071417791822 -0.03452352280094115" rpy="0.08853717963934662 -0.2091803673917457 -0.40396882311318977"/>
    <axis xyz="-9.579078130705909e-08 6.90101362721407e-08 -1.0000003967894144"/>
    <parent link="l_hand_palm"/>
    <child link="l_hand_thumb_1"/>
    <dynamics damping="0.1"/>
  </joint>
  <link name="l_hand_thumb_2">
    <inertial>
      <origin xyz="0.00979199120828872 0.004339703993751887 0.000262957075225112" rpy="1.836586646685542 0.9949596465626955 -2.452146247302006"/>
      <mass value="0.00246082"/>
      <inertia ixx="1.86023e-07" ixy="-1.15428e-08" ixz="-1.55154e-08" iyy="1.58138e-07" iyz="-2.43359e-08" izz="1.86587e-07"/>
    </inertial>
    <visual>
      <origin xyz="-0.09215234480058523 0.2395110056057539 0.21989844725116872" rpy="1.836586646685542 0.9949596465626955 -2.452146247302006"/>
      <geometry>
        <mesh filename="package://ergoCub/meshes/simmechanics/sim_ecub_l_hand_thumb_2_prt.stl" scale="0.001 0.001 0.001"/>
      </geometry>
      <material name="gray">
        <color rgba="0.5 0.5 0.5 1"/>
      </material>
    </visual>
    <collision>
      <origin xyz="-0.09215234480058523 0.2395110056057539 0.21989844725116872" rpy="1.836586646685542 0.9949596465626955 -2.452146247302006"/>
      <geometry>
        <mesh filename="package://ergoCub/meshes/simmechanics/sim_ecub_l_hand_thumb_2_prt.stl" scale="0.001 0.001 0.001"/>
      </geometry>
    </collision>
  </link>
  <joint name="l_thumb_prox" type="continuous">
    <origin xyz="0.0345419043814173 0.0031447987794122334 -0.026071809138455138" rpy="1.3486854426081958 0.6514100961972398 1.2371890149379312e-06"/>
    <axis xyz="-6.65068723482154e-07 2.7824760159833595e-07 1.0000002266902146"/>
    <parent link="l_hand_thumb_1"/>
    <child link="l_hand_thumb_2"/>
    <dynamics damping="0.1"/>
  </joint>
  <link name="l_hand_thumb_3">
    <inertial>
      <origin xyz="0.006464657686845232 0.001884491656128695 1.5530289565829358e-05" rpy="1.836586646685542 0.9949596465626955 -2.452146247302006"/>
      <mass value="0.00811336"/>
      <inertia ixx="1.82522e-06" ixy="-6.71818e-07" ixz="-3.37336e-07" iyy="9.45172e-07" iyz="-6.24005e-07" izz="1.87862e-06"/>
    </inertial>
    <visual>
      <origin xyz="-0.11215186322773271 0.24101052770139614 0.21989803874896868" rpy="1.836586646685542 0.9949596465626955 -2.452146247302006"/>
      <geometry>
        <mesh filename="package://ergoCub/meshes/simmechanics/sim_ecub_l_hand_thumb_3_prt.stl" scale="0.001 0.001 0.001"/>
      </geometry>
      <material name="green">
        <color rgba="0 1 0 1"/>
      </material>
    </visual>
    <collision>
      <origin xyz="-0.11215186322773271 0.24101052770139614 0.21989803874896868" rpy="1.836586646685542 0.9949596465626955 -2.452146247302006"/>
      <geometry>
        <mesh filename="package://ergoCub/meshes/simmechanics/sim_ecub_l_hand_thumb_3_prt.stl" scale="0.001 0.001 0.001"/>
      </geometry>
    </collision>
  </link>
  <joint name="l_thumb_dist" type="continuous">
    <origin xyz="0.019999518427147367 -0.0014995220956423305 4.0850220001109605e-07" rpy="0 0 0"/>
    <axis xyz="-6.65068723482154e-07 2.7824760159833595e-07 1.0000002266902146"/>
    <parent link="l_hand_thumb_2"/>
    <child link="l_hand_thumb_3"/>
    <dynamics damping="0.1"/>
  </joint>
  <link name="l_hand_pinkie_1">
    <inertial>
      <origin xyz="0.00012075789444784824 0.0037048971933640873 -0.011966220252340842" rpy="0.03293841693450851 0.2510502277214382 1.8063707999903837"/>
      <mass value="0.00283627"/>
      <inertia ixx="3.02032e-07" ixy="-2.91649e-09" ixz="3.31954e-08" iyy="3.0208e-07" iyz="-2.28393e-09" izz="1.5695e-07"/>
    </inertial>
    <visual>
      <origin xyz="0.028549811623539253 -0.1994204889078756 0.32262719008362417" rpy="0.03293841693450851 0.2510502277214382 1.8063707999903837"/>
      <geometry>
        <mesh filename="package://ergoCub/meshes/simmechanics/sim_ecub_l_hand_pinkie_1_prt.stl" scale="0.001 0.001 0.001"/>
      </geometry>
      <material name="black">
        <color rgba="0 0 0 1"/>
      </material>
    </visual>
    <collision>
      <origin xyz="0.028549811623539253 -0.1994204889078756 0.32262719008362417" rpy="0.03293841693450851 0.2510502277214382 1.8063707999903837"/>
      <geometry>
        <mesh filename="package://ergoCub/meshes/simmechanics/sim_ecub_l_hand_pinkie_1_prt.stl" scale="0.001 0.001 0.001"/>
      </geometry>
    </collision>
  </link>
  <joint name="l_pinkie_prox" type="continuous">
    <origin xyz="-0.035982242641955084 -0.002388684875026359 -0.09208535104881391" rpy="0 0.08726650590388031 0.026179823381597748"/>
    <axis xyz="-1.0000005135466863 -1.979209419246744e-07 -4.060128685548503e-07"/>
    <parent link="l_hand_palm"/>
    <child link="l_hand_pinkie_1"/>
    <dynamics damping="0.1"/>
  </joint>
  <link name="l_hand_pinkie_2">
    <inertial>
      <origin xyz="1.7125598005506004e-05 0.0017852152950041389 -0.005612274232820069" rpy="0.03294759939428343 0.25108473598814396 1.806373605758749"/>
      <mass value="0.00857923"/>
      <inertia ixx="2.55812e-06" ixy="3.5901e-08" ixz="7.27944e-07" iyy="2.79071e-06" iyz="-1.07962e-07" izz="5.17012e-07"/>
    </inertial>
    <visual>
      <origin xyz="0.028550210609258775 -0.19790833657594356 0.34763445744619553" rpy="0.03294759939428343 0.25108473598814396 1.806373605758749"/>
      <geometry>
        <mesh filename="package://ergoCub/meshes/simmechanics/sim_ecub_l_hand_pinkie_2_prt.stl" scale="0.001 0.001 0.001"/>
      </geometry>
      <material name="red">
        <color rgba="1 0 0 1"/>
      </material>
    </visual>
    <collision>
      <origin xyz="0.028550210609258775 -0.19790833657594356 0.34763445744619553" rpy="0.03294759939428343 0.25108473598814396 1.806373605758749"/>
      <geometry>
        <mesh filename="package://ergoCub/meshes/simmechanics/sim_ecub_l_hand_pinkie_2_prt.stl" scale="0.001 0.001 0.001"/>
      </geometry>
    </collision>
  </link>
  <joint name="l_pinkie_dist" type="continuous">
    <origin xyz="0 -0.0014997508602253018 -0.025000232410908207" rpy="3.5631170772755025e-05 -5.94559868174076e-07 -5.245059638522189e-07"/>
    <axis xyz="-1.0000005135465095 -7.224204564889453e-07 1.88573045758339e-07"/>
    <parent link="l_hand_pinkie_1"/>
    <child link="l_hand_pinkie_2"/>
    <dynamics damping="0.1"/>
  </joint>
  <link name="l_hand_ring_1">
    <inertial>
      <origin xyz="0.00014280339169174278 0.0036426704125520626 -0.014331537616628587" rpy="0.03293841693450851 0.2510502277214382 1.8063707999903837"/>
      <mass value="0.00345703"/>
      <inertia ixx="4.40041e-07" ixy="-2.00998e-09" ixz="5.85772e-08" iyy="4.4829e-07" iyz="-2.27607e-09" izz="1.93821e-07"/>
    </inertial>
    <visual>
      <origin xyz="0.0075498455057530925 -0.19942057587455303 0.326627227033986" rpy="0.03293841693450851 0.2510502277214382 1.8063707999903837"/>
      <geometry>
        <mesh filename="package://ergoCub/meshes/simmechanics/sim_ecub_l_hand_ring_1_prt.stl" scale="0.001 0.001 0.001"/>
      </geometry>
      <material name="blue">
        <color rgba="0 0 1 1"/>
      </material>
    </visual>
    <collision>
      <origin xyz="0.0075498455057530925 -0.19942057587455303 0.326627227033986" rpy="0.03293841693450851 0.2510502277214382 1.8063707999903837"/>
      <geometry>
        <mesh filename="package://ergoCub/meshes/simmechanics/sim_ecub_l_hand_ring_1_prt.stl" scale="0.001 0.001 0.001"/>
      </geometry>
    </collision>
  </link>
  <joint name="l_ring_prox" type="continuous">
    <origin xyz="-0.015417865717831492 -0.0018501027039076468 -0.09790043518642758" rpy="0 0.08726650590388031 0.026179823381597748"/>
    <axis xyz="1.0000005135466863 1.979209419246744e-07 4.060128685548503e-07"/>
    <parent link="l_hand_palm"/>
    <child link="l_hand_ring_1"/>
    <dynamics damping="0.1"/>
  </joint>
  <link name="l_hand_ring_2">
    <inertial>
      <origin xyz="5.158639613809905e-05 0.001599622377635862 -0.0035905977403072886" rpy="0.03293841693450851 0.2510502277214382 1.8063707999903837"/>
      <mass value="0.00912524"/>
      <inertia ixx="3.15499e-06" ixy="4.76252e-08" ixz="9.4436e-07" iyy="3.46575e-06" iyz="-1.39679e-07" izz="5.99879e-07"/>
    </inertial>
    <visual>
      <origin xyz="0.007549803385393976 -0.19792065527302388 0.3566277911453055" rpy="0.03293841693450851 0.2510502277214382 1.8063707999903837"/>
      <geometry>
        <mesh filename="package://ergoCub/meshes/simmechanics/sim_ecub_l_hand_ring_2_prt.stl" scale="0.001 0.001 0.001"/>
      </geometry>
      <material name="yellow">
        <color rgba="1 1 0 1"/>
      </material>
    </visual>
    <collision>
      <origin xyz="0.007549803385393976 -0.19792065527302388 0.3566277911453055" rpy="0.03293841693450851 0.2510502277214382 1.8063707999903837"/>
      <geometry>
        <mesh filename="package://ergoCub/meshes/simmechanics/sim_ecub_l_hand_ring_2_prt.stl" scale="0.001 0.001 0.001"/>
      </geometry>
    </collision>
  </link>
  <joint name="l_ring_dist" type="continuous">
    <origin xyz="0 -0.0014999206015294253 -0.03000056411131863" rpy="0 0 0"/>
    <axis xyz="-1.0000005135466863 -1.979209419246744e-07 -4.060128685548503e-07"/>
    <parent link="l_hand_ring_1"/>
    <child link="l_hand_ring_2"/>
    <dynamics damping="0.1"/>
  </joint>
  <link name="l_hand_middle_1">
    <inertial>
      <origin xyz="0.0001426788707961195 0.0036428237933538443 -0.014331376909090254" rpy="0.12008501986317731 0.2297882840735942 1.8533146530335884"/>
      <mass value="0.00345703"/>
      <inertia ixx="4.42142e-07" ixy="2.33291e-09" ixz="5.3584e-08" iyy="4.46329e-07" iyz="-2.42237e-08" izz="1.93919e-07"/>
    </inertial>
    <visual>
      <origin xyz="0.016178354283930052 -0.19875945050109706 0.329825719961567" rpy="0.12008501986317731 0.2297882840735942 1.8533146530335884"/>
      <geometry>
        <mesh filename="package://ergoCub/meshes/simmechanics/sim_ecub_l_hand_middle_1_prt.stl" scale="0.001 0.001 0.001"/>
      </geometry>
      <material name="pink">
        <color rgba="1 0 1 1"/>
      </material>
    </visual>
    <collision>
      <origin xyz="0.016178354283930052 -0.19875945050109706 0.329825719961567" rpy="0.12008501986317731 0.2297882840735942 1.8533146530335884"/>
      <geometry>
        <mesh filename="package://ergoCub/meshes/simmechanics/sim_ecub_l_hand_middle_1_prt.stl" scale="0.001 0.001 0.001"/>
      </geometry>
    </collision>
  </link>
  <joint name="l_middle_prox" type="continuous">
    <origin xyz="0.009600214668670098 -0.0015008571910166413 -0.10299987654370082" rpy="0 0 0"/>
    <axis xyz="-0.9999998262416893 -3.56920377206707e-07 -2.721582535170075e-07"/>
    <parent link="l_hand_palm"/>
    <child link="l_hand_middle_1"/>
    <dynamics damping="0.1"/>
  </joint>
  <link name="l_hand_middle_2">
    <inertial>
      <origin xyz="5.172124499745051e-05 0.0015996341583801033 -0.003590479003163727" rpy="0.11954926259843997 0.22799029281164018 1.8531928341958708"/>
      <mass value="0.00912524"/>
      <inertia ixx="3.19927e-06" ixy="1.239e-07" ixz="8.75068e-07" iyy="3.41731e-06" iyz="-3.99253e-07" izz="6.05364e-07"/>
    </inertial>
    <visual>
      <origin xyz="0.01617844683646749 -0.19793324107587837 0.35945598778643073" rpy="0.11954926259843997 0.22799029281164018 1.8531928341958708"/>
      <geometry>
        <mesh filename="package://ergoCub/meshes/simmechanics/sim_ecub_l_hand_middle_2_prt.stl" scale="0.001 0.001 0.001"/>
      </geometry>
      <material name="cyan">
        <color rgba="0 1 1 1"/>
      </material>
    </visual>
    <collision>
      <origin xyz="0.01617844683646749 -0.19793324107587837 0.35945598778643073" rpy="0.11954926259843997 0.22799029281164018 1.8531928341958708"/>
      <geometry>
        <mesh filename="package://ergoCub/meshes/simmechanics/sim_ecub_l_hand_middle_2_prt.stl" scale="0.001 0.001 0.001"/>
      </geometry>
    </collision>
  </link>
  <joint name="l_middle_dist" type="continuous">
    <origin xyz="-1.3550150999158683e-07 -0.0014995238274964628 -0.030000203253184976" rpy="-0.0018721728628663644 0 2.576685250299645e-07"/>
    <axis xyz="-0.9999998262417538 -9.878318872787173e-08 -2.5044776373606137e-07"/>
    <parent link="l_hand_middle_1"/>
    <child link="l_hand_middle_2"/>
    <dynamics damping="0.1"/>
  </joint>
  <link name="l_hip_1">
    <inertial>
      <origin xyz="-0.0040696 0.028181399999999995 -0.0007390000000000174" rpy="0 0 1.5707963267948966"/>
      <mass value="2.1611"/>
      <inertia ixx="0.0026053085981014787" ixy="-6.232819775588518e-05" ixz="-9.652072708870984e-07" iyy="0.0021342517479410244" iyz="1.1665895303067703e-05" izz="0.002377428239043109"/>
    </inertial>
    <visual>
      <origin xyz="-0.021099999999999976 -0.0505 0.1785" rpy="0 0 1.5707963267948966"/>
      <geometry>
        <mesh filename="package://ergoCub/meshes/simmechanics/sim_ecub_l_hip_1_prt.stl" scale="0.001 0.001 0.001"/>
      </geometry>
      <material name="l_hip_1_color">
        <color rgba="0.9 0.9 0.9 1"/>
      </material>
    </visual>
    <collision>
      <origin xyz="-0.021099999999999976 -0.0505 0.1785" rpy="0 0 1.5707963267948966"/>
      <geometry>
        <mesh filename="package://ergoCub/meshes/simmechanics/sim_ecub_l_hip_1_prt.stl" scale="0.001 0.001 0.001"/>
      </geometry>
    </collision>
  </link>
  <joint name="l_hip_pitch" type="revolute">
    <origin xyz="0.0211 0.05045 0" rpy="0 0 0"/>
    <axis xyz="0.0 -1.0 0.0"/>
    <parent link="root_link"/>
    <child link="l_hip_1"/>
    <limit effort="50000" lower="-0.7853981633974483" upper="2.007128639793479" velocity="120.0"/>
    <dynamics damping="2.0" friction="0.0"/>
  </joint>
  <link name="l_hip_2">
    <inertial>
      <origin xyz="-0.004125700000000003 3.9200000000017e-05 -0.03750999999999999" rpy="0 0 1.5707963267948966"/>
      <mass value="1.7731"/>
      <inertia ixx="0.005306469525694717" ixy="1.599448667277407e-06" ixz="-2.104052754329713e-06" iyy="0.0030548904888103652" iyz="-0.0009646872984556994" izz="0.003285935714129913"/>
    </inertial>
    <visual>
      <origin xyz="0.026150000000000024 -0.08359999999999998 0.1875" rpy="0 0 1.5707963267948966"/>
      <geometry>
        <mesh filename="package://ergoCub/meshes/simmechanics/sim_ecub_l_hip_2_prt.stl" scale="0.001 0.001 0.001"/>
      </geometry>
      <material name="l_hip_2_color">
        <color rgba="0.9 0.9 0.9 1"/>
      </material>
    </visual>
    <collision>
      <origin xyz="0.026150000000000024 -0.08359999999999998 0.1875" rpy="0 0 1.5707963267948966"/>
      <geometry>
        <mesh filename="package://ergoCub/meshes/simmechanics/sim_ecub_l_hip_2_prt.stl" scale="0.001 0.001 0.001"/>
      </geometry>
    </collision>
  </link>
  <joint name="l_hip_roll" type="revolute">
    <origin xyz="-0.04725 0.03309999999999999 -0.009000000000000008" rpy="0 0 0"/>
    <axis xyz="1.0 0.0 0.0"/>
    <parent link="l_hip_1"/>
    <child link="l_hip_2"/>
    <limit effort="50000" lower="-0.17453292519943295" upper="1.9547687622336491" velocity="120.0"/>
    <dynamics damping="2.0" friction="0.0"/>
  </joint>
  <link name="l_hip_3">
    <inertial>
      <origin xyz="0.0051760999999999995 -0.012828800000000001 -0.05174899999999999" rpy="0 0 1.5707963267948966"/>
      <mass value="2.1622"/>
      <inertia ixx="0.008254059959395023" ixy="3.34403392098793e-05" ixz="0.00012560880606466993" iyy="0.007291726309417373" iyz="-2.5233117251527342e-05" izz="0.0057666117251527335"/>
    </inertial>
    <visual>
      <origin xyz="-0.010549999999999926 -0.08360000000000002 0.2772" rpy="0 0 1.5707963267948966"/>
      <geometry>
        <mesh filename="package://ergoCub/meshes/simmechanics/sim_ecub_l_hip_3_prt.stl" scale="0.001 0.001 0.001"/>
      </geometry>
      <material name="l_hip_3_color">
        <color rgba="0.3 0.3 0.3 1"/>
      </material>
    </visual>
    <collision>
      <origin xyz="-0.010549999999999926 -0.08360000000000002 0.2772" rpy="0 0 1.5707963267948966"/>
      <geometry>
        <mesh filename="package://ergoCub/meshes/simmechanics/sim_ecub_l_hip_3_prt.stl" scale="0.001 0.001 0.001"/>
      </geometry>
    </collision>
  </link>
  <joint name="l_leg_ft_sensor" type="fixed">
    <origin xyz="0.036699999999999997 0 -0.0897" rpy="0 0 0"/>
    <parent link="l_hip_2"/>
    <child link="l_hip_3"/>
    <dynamics damping="0.1"/>
  </joint>
  <link name="l_upper_leg">
    <inertial>
      <origin xyz="0.0085035 0.014484900000000009 -0.126747" rpy="0 0 1.5707963267948966"/>
      <mass value="0.90926"/>
      <inertia ixx="0.00395381112347931" ixy="1.6022339713169497e-05" ixz="0.00012803238304152364" iyy="0.003869738888011146" iyz="-0.0001761106009292906" izz="0.0007357969398761904"/>
    </inertial>
    <visual>
      <origin xyz="-0.01055000000000001 -0.06860000000000005 0.3499" rpy="0 0 1.5707963267948966"/>
      <geometry>
        <mesh filename="package://ergoCub/meshes/simmechanics/sim_ecub_l_upper_leg_prt.stl" scale="0.001 0.001 0.001"/>
      </geometry>
      <material name="l_upper_leg_color">
        <color rgba="0.9 0.9 0.9 1"/>
      </material>
    </visual>
    <collision>
      <origin xyz="-0.01055000000000001 -0.06860000000000005 0.3499" rpy="0 0 1.5707963267948966"/>
      <geometry>
        <mesh filename="package://ergoCub/meshes/simmechanics/sim_ecub_l_upper_leg_prt.stl" scale="0.001 0.001 0.001"/>
      </geometry>
    </collision>
  </link>
  <joint name="l_hip_yaw" type="revolute">
    <origin xyz="0 -0.015 -0.07269999999999999" rpy="0 0 0"/>
    <axis xyz="0.0 0.0 1.0"/>
    <parent link="l_hip_3"/>
    <child link="l_upper_leg"/>
    <limit effort="50000" lower="-1.3962634015954636" upper="1.3962634015954636" velocity="120.0"/>
    <dynamics damping="2.0" friction="0.0"/>
  </joint>
  <link name="l_lower_leg">
    <inertial>
      <origin xyz="0.0013845000000000038 -0.006187100000000001 0.21426" rpy="3.141592653589793 0 -1.5707963267948966"/>
      <mass value="5.0486"/>
      <inertia ixx="0.06375675529518042" ixy="2.5807754619000915e-05" ixz="0.0024591349675674376" iyy="0.06208563214231307" iyz="0.001086367679207614" izz="0.0064532205013349865"/>
    </inertial>
    <visual>
      <origin xyz="-0.021150000000000016 0.06070000000000036 -0.5296000000000004" rpy="3.141592653589793 0 -1.5707963267948966"/>
      <geometry>
        <mesh filename="package://ergoCub/meshes/simmechanics/sim_ecub_l_lower_leg_prt.stl" scale="0.001 0.001 0.001"/>
      </geometry>
      <material name="l_lower_leg_color">
        <color rgba="0.3 0.3 0.3 1"/>
      </material>
    </visual>
    <collision>
      <origin xyz="-0.021150000000000016 0.06070000000000036 -0.5296000000000004" rpy="3.141592653589793 0 -1.5707963267948966"/>
      <geometry>
        <mesh filename="package://ergoCub/meshes/simmechanics/sim_ecub_l_lower_leg_prt.stl" scale="0.001 0.001 0.001"/>
      </geometry>
    </collision>
  </link>
  <joint name="l_knee" type="revolute">
    <origin xyz="0.010599999999999998 -0.00789999999999999 -0.17970000000000008" rpy="3.141592653589793 0 0"/>
    <axis xyz="0.0 -1.0 0.0"/>
    <parent link="l_upper_leg"/>
    <child link="l_lower_leg"/>
    <limit effort="50000" lower="-1.2217304763960306" upper="0.08726646259971647" velocity="120.0"/>
    <dynamics damping="2.0" friction="0.0"/>
  </joint>
  <link name="l_ankle_1">
    <inertial>
      <origin xyz="-0.0013851999999999962 0.0006601999999999997 -0.01408699999999996" rpy="0 0 1.5707963267948966"/>
      <mass value="0.36569"/>
      <inertia ixx="0.01" ixy="9.330027898933727e-06" ixz="-5.8027845674579475e-05" iyy="0.01" iyz="8.26578856828523e-06" izz="0.01"/>
    </inertial>
    <visual>
      <origin xyz="-0.021150000000000165 -0.09260000000000018 0.8506000000000005" rpy="0 0 1.5707963267948966"/>
      <geometry>
        <mesh filename="package://ergoCub/meshes/simmechanics/sim_ecub_l_ankle_1_prt.stl" scale="0.001 0.001 0.001"/>
      </geometry>
      <material name="l_ankle_1_color">
        <color rgba="0.9 0.9 0.9 1"/>
      </material>
    </visual>
    <collision>
      <origin xyz="-0.021150000000000165 -0.09260000000000018 0.8506000000000005" rpy="0 0 1.5707963267948966"/>
      <geometry>
        <mesh filename="package://ergoCub/meshes/simmechanics/sim_ecub_l_ankle_1_prt.stl" scale="0.001 0.001 0.001"/>
      </geometry>
    </collision>
  </link>
  <joint name="l_ankle_pitch" type="revolute">
    <origin xyz="0 -0.0319 0.32099999999999995" rpy="3.141592653589793 0 0"/>
    <axis xyz="0.0 1.0 0.0"/>
    <parent link="l_lower_leg"/>
    <child link="l_ankle_1"/>
    <limit effort="50000" lower="-0.7853981633974483" upper="0.7853981633974483" velocity="120.0"/>
    <dynamics damping="2.0" friction="0.0"/>
  </joint>
  <link name="l_ankle_2">
    <inertial>
      <origin xyz="0.0405224 -9.790000000001187e-05 -0.023870999999999976" rpy="0 0 1.5707963267948966"/>
      <mass value="1.377"/>
      <inertia ixx="0.01" ixy="-1.783842938864459e-05" ixz="-1.3443125267540957e-05" iyy="0.01" iyz="-0.001183474082577733" izz="0.01"/>
    </inertial>
    <visual>
      <origin xyz="0.031599999999999906 -0.07440000000000055 0.8856000000000006" rpy="0 0 1.5707963267948966"/>
      <geometry>
        <mesh filename="package://ergoCub/meshes/simmechanics/sim_ecub_l_ankle_2_prt.stl" scale="0.001 0.001 0.001"/>
      </geometry>
      <material name="l_ankle_2_color">
        <color rgba="0.3 0.3 0.3 1"/>
      </material>
    </visual>
    <collision>
      <origin xyz="0.031599999999999906 -0.07440000000000055 0.8856000000000006" rpy="0 0 1.5707963267948966"/>
      <geometry>
        <mesh filename="package://ergoCub/meshes/simmechanics/sim_ecub_l_ankle_2_prt.stl" scale="0.001 0.001 0.001"/>
      </geometry>
    </collision>
  </link>
  <joint name="l_ankle_roll" type="revolute">
    <origin xyz="-0.052750000000000005 -0.018199999999999994 -0.03500000000000003" rpy="0 0 0"/>
    <axis xyz="1.0 0.0 0.0"/>
    <parent link="l_ankle_1"/>
    <child link="l_ankle_2"/>
    <limit effort="50000" lower="-0.4363323129985824" upper="0.4363323129985824" velocity="120.0"/>
    <dynamics damping="2.0" friction="0.0"/>
  </joint>
  <link name="l_foot_rear">
    <inertial>
      <origin xyz="0.0005878999999999988 0 0.00229899999999994" rpy="0 0 1.5707963267948966"/>
      <mass value="0.17851"/>
      <inertia ixx="0.01" ixy="0.0" ixz="-4.626130186562945e-09" iyy="0.01" iyz="2.656888892607585e-09" izz="0.01"/>
    </inertial>
    <visual>
      <origin xyz="0.015599999999999909 -0.07440000000000056 0.9558000000000011" rpy="0 0 1.5707963267948966"/>
      <geometry>
        <mesh filename="package://ergoCub/meshes/simmechanics/sim_ecub_l_foot_rear_prt.stl" scale="0.001 0.001 0.001"/>
      </geometry>
      <material name="l_foot_rear_color">
        <color rgba="1 0.51 0.0 1"/>
      </material>
    </visual>
    <collision>
      <origin xyz="0.0 0.0 0.003" rpy="0.0 0.0 0.0"/>
      <geometry>
        <box size="0.117 0.1 0.006"/>
      </geometry>
    </collision>
  </link>
  <joint name="l_foot_rear_ft_sensor" type="fixed">
    <origin xyz="0.016000000000000004 0 -0.07019999999999993" rpy="0 0 0"/>
    <parent link="l_ankle_2"/>
    <child link="l_foot_rear"/>
    <dynamics damping="0.1"/>
  </joint>
  <link name="l_foot_front">
    <inertial>
      <origin xyz="0.0005879999999999913 0 0.00229899999999994" rpy="0 0 1.5707963267948966"/>
      <mass value="0.17896"/>
      <inertia ixx="0.01" ixy="0.0" ixz="-4.637792046312838e-09" iyy="0.01" iyz="4.184420777458674e-09" izz="0.01"/>
    </inertial>
    <visual>
      <origin xyz="-0.10365000000000019 -0.07440000000000048 0.955800000000001" rpy="0 0 1.5707963267948966"/>
      <geometry>
        <mesh filename="package://ergoCub/meshes/simmechanics/sim_ecub_l_foot_front_prt.stl" scale="0.001 0.001 0.001"/>
      </geometry>
      <material name="l_foot_front_color">
        <color rgba="1 0.51 0.0 1"/>
      </material>
    </visual>
    <collision>
      <origin xyz="0.0 0.0 0.003" rpy="0.0 0.0 0.0"/>
      <geometry>
        <box size="0.117 0.1 0.006"/>
      </geometry>
    </collision>
  </link>
  <joint name="l_foot_front_ft_sensor" type="fixed">
    <origin xyz="0.13525 0 -0.07019999999999993" rpy="0 0 0"/>
    <parent link="l_ankle_2"/>
    <child link="l_foot_front"/>
    <dynamics damping="0.1"/>
  </joint>
  <link name="r_hip_1">
    <inertial>
      <origin xyz="-0.004091800000000003 -0.0281729 -0.0007410000000000194" rpy="0 0 1.5707963267948966"/>
      <mass value="2.1623"/>
      <inertia ixx="0.0026074574304579875" ixy="6.401962518011122e-05" ixz="7.520611770858115e-07" iyy="0.002135394880576715" iyz="1.119561619811562e-05" izz="0.002378744503296989"/>
    </inertial>
    <visual>
      <origin xyz="-0.021099999999984832 0.0505 0.1785000000000018" rpy="0 0 1.5707963267948966"/>
      <geometry>
        <mesh filename="package://ergoCub/meshes/simmechanics/sim_ecub_r_hip_1_prt.stl" scale="0.001 0.001 0.001"/>
      </geometry>
      <material name="r_hip_1_color">
        <color rgba="0.9 0.9 0.9 1"/>
      </material>
    </visual>
    <collision>
      <origin xyz="-0.021099999999984832 0.0505 0.1785000000000018" rpy="0 0 1.5707963267948966"/>
      <geometry>
        <mesh filename="package://ergoCub/meshes/simmechanics/sim_ecub_r_hip_1_prt.stl" scale="0.001 0.001 0.001"/>
      </geometry>
    </collision>
  </link>
  <joint name="r_hip_pitch" type="revolute">
    <origin xyz="0.0211 -0.050550000000000005 0" rpy="0 0 0"/>
    <axis xyz="0.0 -1.0 0.0"/>
    <parent link="root_link"/>
    <child link="r_hip_1"/>
    <limit effort="50000" lower="-0.7853981633974483" upper="2.007128639793479" velocity="120.0"/>
    <dynamics damping="2.0" friction="0.0"/>
  </joint>
  <link name="r_hip_2">
    <inertial>
      <origin xyz="-0.004133600000000001 -4.650000000000487e-05 -0.03744" rpy="0 0 1.5707963267948966"/>
      <mass value="1.7731"/>
      <inertia ixx="0.0052345420293411875" ixy="-2.158016260362129e-06" ixz="-6.707899551701571e-07" iyy="0.0029826296029668415" iyz="-0.0009566433428773996" izz="0.0032848476128926702"/>
    </inertial>
    <visual>
      <origin xyz="0.026200000000015138 0.08360000000001595 0.1874999999999947" rpy="0 0 1.5707963267948966"/>
      <geometry>
        <mesh filename="package://ergoCub/meshes/simmechanics/sim_ecub_r_hip_2_prt.stl" scale="0.001 0.001 0.001"/>
      </geometry>
      <material name="r_hip_2_color">
        <color rgba="0.9 0.9 0.9 1"/>
      </material>
    </visual>
    <collision>
      <origin xyz="0.026200000000015138 0.08360000000001595 0.1874999999999947" rpy="0 0 1.5707963267948966"/>
      <geometry>
        <mesh filename="package://ergoCub/meshes/simmechanics/sim_ecub_r_hip_2_prt.stl" scale="0.001 0.001 0.001"/>
      </geometry>
    </collision>
  </link>
  <joint name="r_hip_roll" type="revolute">
    <origin xyz="-0.0473 -0.03309999999999999 -0.009000000000000008" rpy="0 0 0"/>
    <axis xyz="-1.0 0.0 0.0"/>
    <parent link="r_hip_1"/>
    <child link="r_hip_2"/>
    <limit effort="50000" lower="-0.17453292519943295" upper="1.9547687622336491" velocity="120.0"/>
    <dynamics damping="2.0" friction="0.0"/>
  </joint>
  <link name="r_hip_3">
    <inertial>
      <origin xyz="0.005151000000000001 0.012832099999999999 -0.051687999999999956" rpy="0 0 1.5707963267948966"/>
      <mass value="2.1635"/>
      <inertia ixx="0.008208205582196565" ixy="-3.524211462358583e-05" ixz="-0.00012664920899483216" iyy="0.007245503985287957" iyz="-2.4278057870478145e-05" izz="0.005769430702081103"/>
    </inertial>
    <visual>
      <origin xyz="-0.01049999999998486 0.08360000000001595 0.27719999999999473" rpy="0 0 1.5707963267948966"/>
      <geometry>
        <mesh filename="package://ergoCub/meshes/simmechanics/sim_ecub_r_hip_3_prt.stl" scale="0.001 0.001 0.001"/>
      </geometry>
      <material name="r_hip_3_color">
        <color rgba="0.3 0.3 0.3 1"/>
      </material>
    </visual>
    <collision>
      <origin xyz="-0.01049999999998486 0.08360000000001595 0.27719999999999473" rpy="0 0 1.5707963267948966"/>
      <geometry>
        <mesh filename="package://ergoCub/meshes/simmechanics/sim_ecub_r_hip_3_prt.stl" scale="0.001 0.001 0.001"/>
      </geometry>
    </collision>
  </link>
  <joint name="r_leg_ft_sensor" type="fixed">
    <origin xyz="0.0367 0 -0.0897" rpy="0 0 0"/>
    <parent link="r_hip_2"/>
    <child link="r_hip_3"/>
    <dynamics damping="0.1"/>
  </joint>
  <link name="r_upper_leg">
    <inertial>
      <origin xyz="0.008517499999999999 -0.014468500000000009 -0.12674999999999997" rpy="0 0 1.5707963267948966"/>
      <mass value="0.90926"/>
      <inertia ixx="0.003953615227008316" ixy="-1.7812180469816007e-05" ixz="-0.00013168128130790113" iyy="0.0038723181915458972" iyz="-0.0001760991736351493" izz="0.0007381934067046809"/>
    </inertial>
    <visual>
      <origin xyz="-0.010499999999984893 0.06860000000001601 0.3498999999999947" rpy="0 0 1.5707963267948966"/>
      <geometry>
        <mesh filename="package://ergoCub/meshes/simmechanics/sim_ecub_r_upper_leg_prt.stl" scale="0.001 0.001 0.001"/>
      </geometry>
      <material name="r_upper_leg_color">
        <color rgba="0.9 0.9 0.9 1"/>
      </material>
    </visual>
    <collision>
      <origin xyz="-0.010499999999984893 0.06860000000001601 0.3498999999999947" rpy="0 0 1.5707963267948966"/>
      <geometry>
        <mesh filename="package://ergoCub/meshes/simmechanics/sim_ecub_r_upper_leg_prt.stl" scale="0.001 0.001 0.001"/>
      </geometry>
    </collision>
  </link>
  <joint name="r_hip_yaw" type="revolute">
    <origin xyz="0 0.015 -0.07269999999999999" rpy="0 0 0"/>
    <axis xyz="0.0 0.0 -1.0"/>
    <parent link="r_hip_3"/>
    <child link="r_upper_leg"/>
    <limit effort="50000" lower="-1.3962634015954636" upper="1.3962634015954636" velocity="120.0"/>
    <dynamics damping="2.0" friction="0.0"/>
  </joint>
  <link name="r_lower_leg">
    <inertial>
      <origin xyz="0.0011584999999999998 0.006200199999999989 0.21425899999999998" rpy="3.141592653589793 0 -1.5707963267948966"/>
      <mass value="5.0761"/>
      <inertia ixx="0.06410811181015659" ixy="-4.625064160882615e-05" ixz="-0.0024668184631749432" iyy="0.06242530830043752" iyz="0.001155162395706661" izz="0.006491831033966662"/>
    </inertial>
    <visual>
      <origin xyz="-0.02109999999998385 -0.060700000000016026 -0.5295999999999949" rpy="3.141592653589793 0 -1.5707963267948966"/>
      <geometry>
        <mesh filename="package://ergoCub/meshes/simmechanics/sim_ecub_r_lower_leg_prt.stl" scale="0.001 0.001 0.001"/>
      </geometry>
      <material name="r_lower_leg_color">
        <color rgba="0.3 0.3 0.3 1"/>
      </material>
    </visual>
    <collision>
      <origin xyz="-0.02109999999998385 -0.060700000000016026 -0.5295999999999949" rpy="3.141592653589793 0 -1.5707963267948966"/>
      <geometry>
        <mesh filename="package://ergoCub/meshes/simmechanics/sim_ecub_r_lower_leg_prt.stl" scale="0.001 0.001 0.001"/>
      </geometry>
    </collision>
  </link>
  <joint name="r_knee" type="revolute">
    <origin xyz="0.0106 0.00789999999999999 -0.17970000000000008" rpy="3.141592653589793 0 0"/>
    <axis xyz="0.0 -1.0 0.0"/>
    <parent link="r_upper_leg"/>
    <child link="r_lower_leg"/>
    <limit effort="50000" lower="-1.2217304763960306" upper="0.08726646259971647" velocity="120.0"/>
    <dynamics damping="2.0" friction="0.0"/>
  </joint>
  <link name="r_ankle_1">
    <inertial>
      <origin xyz="-0.001367199999999999 -0.0006601999999999997 -0.01408699999999996" rpy="0 0 1.5707963267948966"/>
      <mass value="0.36569"/>
      <inertia ixx="0.01" ixy="-9.445440506652726e-06" ixz="5.8027845674579475e-05" iyy="0.01" iyz="1.0858575291272177e-05" izz="0.01"/>
    </inertial>
    <visual>
      <origin xyz="-0.021100000000058197 0.092600000000016 0.8505999999999929" rpy="0 0 1.5707963267948966"/>
      <geometry>
        <mesh filename="package://ergoCub/meshes/simmechanics/sim_ecub_r_ankle_1_prt.stl" scale="0.001 0.001 0.001"/>
      </geometry>
      <material name="r_ankle_1_color">
        <color rgba="0.9 0.9 0.9 1"/>
      </material>
    </visual>
    <collision>
      <origin xyz="-0.021100000000058197 0.092600000000016 0.8505999999999929" rpy="0 0 1.5707963267948966"/>
      <geometry>
        <mesh filename="package://ergoCub/meshes/simmechanics/sim_ecub_r_ankle_1_prt.stl" scale="0.001 0.001 0.001"/>
      </geometry>
    </collision>
  </link>
  <joint name="r_ankle_pitch" type="revolute">
    <origin xyz="0 0.0319 0.32099999999999995" rpy="3.141592653589793 0 0"/>
    <axis xyz="0.0 1.0 0.0"/>
    <parent link="r_lower_leg"/>
    <child link="r_ankle_1"/>
    <limit effort="50000" lower="-0.7853981633974483" upper="0.7853981633974483" velocity="120.0"/>
    <dynamics damping="2.0" friction="0.0"/>
  </joint>
  <link name="r_ankle_2">
    <inertial>
      <origin xyz="0.040526469999999995 -8.640000000000037e-05 -0.023870999999999976" rpy="0 0 1.5707963267948966"/>
      <mass value="1.3771"/>
      <inertia ixx="0.01" ixy="-2.0606036165051692e-05" ixz="-2.748492674242129e-05" iyy="0.01" iyz="-0.0011810948923998911" izz="0.01"/>
    </inertial>
    <visual>
      <origin xyz="0.031649999999941794 0.07439999999994094 0.8855999999999997" rpy="0 0 1.5707963267948966"/>
      <geometry>
        <mesh filename="package://ergoCub/meshes/simmechanics/sim_ecub_r_ankle_2_prt.stl" scale="0.001 0.001 0.001"/>
      </geometry>
      <material name="r_ankle_2_color">
        <color rgba="0.3 0.3 0.3 1"/>
      </material>
    </visual>
    <collision>
      <origin xyz="0.031649999999941794 0.07439999999994094 0.8855999999999997" rpy="0 0 1.5707963267948966"/>
      <geometry>
        <mesh filename="package://ergoCub/meshes/simmechanics/sim_ecub_r_ankle_2_prt.stl" scale="0.001 0.001 0.001"/>
      </geometry>
    </collision>
  </link>
  <joint name="r_ankle_roll" type="revolute">
    <origin xyz="-0.05275 0.018199999999999994 -0.03500000000000003" rpy="0 0 0"/>
    <axis xyz="-1.0 0.0 0.0"/>
    <parent link="r_ankle_1"/>
    <child link="r_ankle_2"/>
    <limit effort="50000" lower="-0.4363323129985824" upper="0.4363323129985824" velocity="120.0"/>
    <dynamics damping="2.0" friction="0.0"/>
  </joint>
  <link name="r_foot_front">
    <inertial>
      <origin xyz="0.0005880000000000052 0 0.00229899999999994" rpy="0 0 1.5707963267948966"/>
      <mass value="0.17964"/>
      <inertia ixx="0.01" ixy="0.0" ixz="-3.469232248931503e-09" iyy="0.01" iyz="3.2471287831573237e-09" izz="0.01"/>
    </inertial>
    <visual>
      <origin xyz="-0.10360000000005821 0.07439999999994093 0.9557999999999999" rpy="0 0 1.5707963267948966"/>
      <geometry>
        <mesh filename="package://ergoCub/meshes/simmechanics/sim_ecub_r_foot_front_prt.stl" scale="0.001 0.001 0.001"/>
      </geometry>
      <material name="r_foot_front_color">
        <color rgba="1 0.51 0.0 1"/>
      </material>
    </visual>
    <collision>
      <origin xyz="0.0 0.0 0.003" rpy="0.0 0.0 0.0"/>
      <geometry>
        <box size="0.117 0.1 0.006"/>
      </geometry>
    </collision>
  </link>
  <joint name="r_foot_front_ft_sensor" type="fixed">
    <origin xyz="0.13524999999999998 0 -0.07019999999999993" rpy="0 0 0"/>
    <parent link="r_ankle_2"/>
    <child link="r_foot_front"/>
    <dynamics damping="0.1"/>
  </joint>
  <link name="r_foot_rear">
    <inertial>
      <origin xyz="0.0005879000000000006 0 0.00229899999999994" rpy="0 0 1.5707963267948966"/>
      <mass value="0.17874"/>
      <inertia ixx="0.01" ixy="0.0" ixz="-3.4518513258406643e-09" iyy="0.01" iyz="0.0" izz="0.01"/>
    </inertial>
    <visual>
      <origin xyz="0.015649999999941794 0.07439999999994094 0.9557999999999999" rpy="0 0 1.5707963267948966"/>
      <geometry>
        <mesh filename="package://ergoCub/meshes/simmechanics/sim_ecub_r_foot_rear_prt.stl" scale="0.001 0.001 0.001"/>
      </geometry>
      <material name="r_foot_rear_color">
        <color rgba="1 0.51 0.0 1"/>
      </material>
    </visual>
    <collision>
      <origin xyz="0.0 0.0 0.003" rpy="0.0 0.0 0.0"/>
      <geometry>
        <box size="0.117 0.1 0.006"/>
      </geometry>
    </collision>
  </link>
  <joint name="r_foot_rear_ft_sensor" type="fixed">
    <origin xyz="0.015999999999999997 0 -0.07019999999999993" rpy="0 0 0"/>
    <parent link="r_ankle_2"/>
    <child link="r_foot_rear"/>
    <dynamics damping="0.1"/>
  </joint>
  <link name="base_link"/>
  <joint name="base_link_fixed_joint" type="fixed">
  <origin xyz="0 0 0" rpy="0 -0 0"/>
  <axis xyz="0 0 0"/>
  <parent link="root_link"/>
  <child link="base_link"/>
</joint>
  <gazebo reference="r_arm_ft_sensor">
<preserveFixedJoint>true</preserveFixedJoint>
<!-- For compatibility with SDFormat < 4.4 -->
<disableFixedJointLumping>true</disableFixedJointLumping>
</gazebo>
  <gazebo reference="l_arm_ft_sensor">
<preserveFixedJoint>true</preserveFixedJoint>
<!-- For compatibility with SDFormat < 4.4 -->
<disableFixedJointLumping>true</disableFixedJointLumping>
</gazebo>
  <gazebo>
<plugin name="controlboard_torso" filename="libgazebo_yarp_controlboard.so">
  <yarpConfigurationFile>model://ergoCub/conf/gazebo_ergocub_torso.ini</yarpConfigurationFile>
</plugin>
</gazebo>
  <gazebo reference="torso_pitch">
    <implicitSpringDamper>1</implicitSpringDamper>
</gazebo>
  <gazebo reference="torso_roll">
    <implicitSpringDamper>1</implicitSpringDamper>
</gazebo>
  <gazebo reference="torso_yaw">
    <implicitSpringDamper>1</implicitSpringDamper>
</gazebo>
  <gazebo reference="r_shoulder_pitch">
    <implicitSpringDamper>1</implicitSpringDamper>
</gazebo>
  <gazebo reference="r_shoulder_roll">
    <implicitSpringDamper>1</implicitSpringDamper>
</gazebo>
  <gazebo reference="r_shoulder_yaw">
    <implicitSpringDamper>1</implicitSpringDamper>
</gazebo>
  <gazebo reference="l_shoulder_pitch">
    <implicitSpringDamper>1</implicitSpringDamper>
</gazebo>
  <gazebo reference="l_shoulder_roll">
    <implicitSpringDamper>1</implicitSpringDamper>
</gazebo>
  <gazebo reference="l_shoulder_yaw">
    <implicitSpringDamper>1</implicitSpringDamper>
</gazebo>
  <gazebo reference="l_leg_ft_sensor">
<preserveFixedJoint>true</preserveFixedJoint>
<!-- For compatibility with SDFormat < 4.4 -->
<disableFixedJointLumping>true</disableFixedJointLumping>
</gazebo>
  <gazebo reference="l_foot_front_ft_sensor">
<preserveFixedJoint>true</preserveFixedJoint>
<!-- For compatibility with SDFormat < 4.4 -->
<disableFixedJointLumping>true</disableFixedJointLumping>
</gazebo>
  <gazebo reference="l_foot_rear_ft_sensor">
<preserveFixedJoint>true</preserveFixedJoint>
<!-- For compatibility with SDFormat < 4.4 -->
<disableFixedJointLumping>true</disableFixedJointLumping>
</gazebo>
  <gazebo reference="l_foot_front">
  <collision> <surface> <bounce>
    <restitution_coefficient>0</restitution_coefficient>
    <threshold>100000</threshold>
  </bounce> </surface> </collision>
  <maxContacts>4</maxContacts>
  <kp>18000000</kp>
  <kd>100</kd>
  <maxVel>100</maxVel>
  <minDepth>0.0001</minDepth>
  <mu1>1</mu1>
  <mu2>1</mu2>
  <fdir1>0 0 0</fdir1>
</gazebo>
  <gazebo reference="l_foot_rear">
  <collision> <surface> <bounce>
    <restitution_coefficient>0</restitution_coefficient>
    <threshold>100000</threshold>
  </bounce> </surface> </collision>
  <maxContacts>4</maxContacts>
  <kp>18000000</kp>
  <kd>100</kd>
  <maxVel>100</maxVel>
  <minDepth>0.0001</minDepth>
  <mu1>1</mu1>
  <mu2>1</mu2>
  <fdir1>0 0 0</fdir1>
</gazebo>
  <gazebo>
<plugin name="controlboard_left_leg" filename="libgazebo_yarp_controlboard.so">
<yarpConfigurationFile>model://ergoCub/conf/gazebo_ergocub_left_leg.ini</yarpConfigurationFile>
</plugin>
</gazebo>
  <gazebo reference="l_hip_pitch">
    <implicitSpringDamper>1</implicitSpringDamper>
</gazebo>
  <gazebo reference="l_hip_roll">
    <implicitSpringDamper>1</implicitSpringDamper>
</gazebo>
  <gazebo reference="l_hip_yaw">
    <implicitSpringDamper>1</implicitSpringDamper>
</gazebo>
  <gazebo reference="l_knee">
    <implicitSpringDamper>1</implicitSpringDamper>
</gazebo>
  <gazebo reference="l_ankle_pitch">
    <implicitSpringDamper>1</implicitSpringDamper>
</gazebo>
  <gazebo reference="l_ankle_roll">
    <implicitSpringDamper>1</implicitSpringDamper>
</gazebo>
  <gazebo reference="r_leg_ft_sensor">
<preserveFixedJoint>true</preserveFixedJoint>
<!-- For compatibility with SDFormat < 4.4 -->
<disableFixedJointLumping>true</disableFixedJointLumping>
</gazebo>
  <gazebo reference="r_foot_front_ft_sensor">
<preserveFixedJoint>true</preserveFixedJoint>
<!-- For compatibility with SDFormat < 4.4 -->
<disableFixedJointLumping>true</disableFixedJointLumping>
</gazebo>
  <gazebo reference="r_foot_rear_ft_sensor">
<preserveFixedJoint>true</preserveFixedJoint>
<!-- For compatibility with SDFormat < 4.4 -->
<disableFixedJointLumping>true</disableFixedJointLumping>
</gazebo>
  <gazebo reference="r_foot_front">
  <collision> <surface> <bounce>
    <restitution_coefficient>0</restitution_coefficient>
    <threshold>100000</threshold>
  </bounce> </surface> </collision>
  <maxContacts>4</maxContacts>
  <kp>18000000</kp>
  <kd>100</kd>
  <maxVel>100</maxVel>
  <minDepth>0.0001</minDepth>
  <mu1>1</mu1>
  <mu2>1</mu2>
  <fdir1>0 0 0</fdir1>
</gazebo>
  <gazebo reference="r_foot_rear">
  <collision> <surface> <bounce>
    <restitution_coefficient>0</restitution_coefficient>
    <threshold>100000</threshold>
  </bounce> </surface> </collision>
  <maxContacts>4</maxContacts>
  <kp>18000000</kp>
  <kd>100</kd>
  <maxVel>100</maxVel>
  <minDepth>0.0001</minDepth>
  <mu1>1</mu1>
  <mu2>1</mu2>
  <fdir1>0 0 0</fdir1>
</gazebo>
  <gazebo>
<plugin name="controlboard_right_leg" filename="libgazebo_yarp_controlboard.so">
<yarpConfigurationFile>model://ergoCub/conf/gazebo_ergocub_right_leg.ini</yarpConfigurationFile>
</plugin>
</gazebo>
  <gazebo reference="r_hip_pitch">
    <implicitSpringDamper>1</implicitSpringDamper>
</gazebo>
  <gazebo reference="r_hip_roll">
    <implicitSpringDamper>1</implicitSpringDamper>
</gazebo>
  <gazebo reference="r_hip_yaw">
    <implicitSpringDamper>1</implicitSpringDamper>
</gazebo>
  <gazebo reference="r_knee">
    <implicitSpringDamper>1</implicitSpringDamper>
</gazebo>
  <gazebo reference="r_ankle_pitch">
    <implicitSpringDamper>1</implicitSpringDamper>
</gazebo>
  <gazebo reference="r_ankle_roll">
    <implicitSpringDamper>1</implicitSpringDamper>
</gazebo>
  <gazebo>
<plugin name="controlboard_head_without_eyes" filename="libgazebo_yarp_controlboard.so">
<yarpConfigurationFile>model://ergoCub/conf/gazebo_ergocub_head.ini</yarpConfigurationFile>
</plugin>
</gazebo>
  <gazebo reference="neck_pitch">
    <implicitSpringDamper>1</implicitSpringDamper>
</gazebo>
  <gazebo reference="neck_roll">
    <implicitSpringDamper>1</implicitSpringDamper>
</gazebo>
  <gazebo reference="neck_yaw">
    <implicitSpringDamper>1</implicitSpringDamper>
</gazebo>
  <gazebo>
<plugin name="controlboard_left_arm_no_hand" filename="libgazebo_yarp_controlboard.so">
<yarpConfigurationFile>model://ergoCub/conf/gazebo_ergocub_left_arm.ini</yarpConfigurationFile>
<initialConfiguration>-0.52 0.52 0 0.785 0 0 0.0</initialConfiguration>
</plugin>
</gazebo>
  <gazebo reference="l_shoulder_pitch">
  <implicitSpringDamper>1</implicitSpringDamper>
</gazebo>
  <gazebo reference="l_shoulder_roll">
  <implicitSpringDamper>1</implicitSpringDamper>
</gazebo>
  <gazebo reference="l_shoulder_yaw">
  <implicitSpringDamper>1</implicitSpringDamper>
</gazebo>
  <gazebo reference="l_elbow">
  <implicitSpringDamper>1</implicitSpringDamper>
</gazebo>
  <gazebo reference="l_wrist_prosup">
  <implicitSpringDamper>1</implicitSpringDamper>
</gazebo>
  <gazebo reference="l_wrist_pitch">
  <implicitSpringDamper>1</implicitSpringDamper>
</gazebo>
  <gazebo reference="l_wrist_yaw">
  <implicitSpringDamper>1</implicitSpringDamper>
</gazebo>
  <gazebo>
<plugin name="controlboard_right_arm_no_hand" filename="libgazebo_yarp_controlboard.so">
<yarpConfigurationFile>model://ergoCub/conf/gazebo_ergocub_right_arm.ini</yarpConfigurationFile>
<initialConfiguration>-0.52 0.52 0 0.785 0 0 0.0</initialConfiguration>
</plugin>
</gazebo>
  <gazebo reference="r_shoulder_pitch">
  <implicitSpringDamper>1</implicitSpringDamper>
</gazebo>
  <gazebo reference="r_shoulder_roll">
  <implicitSpringDamper>1</implicitSpringDamper>
</gazebo>
  <gazebo reference="r_shoulder_yaw">
  <implicitSpringDamper>1</implicitSpringDamper>
</gazebo>
  <gazebo reference="r_elbow">
  <implicitSpringDamper>1</implicitSpringDamper>
</gazebo>
  <gazebo reference="r_wrist_prosup">
  <implicitSpringDamper>1</implicitSpringDamper>
</gazebo>
  <gazebo reference="r_wrist_pitch">
  <implicitSpringDamper>1</implicitSpringDamper>
</gazebo>
  <gazebo reference="r_wrist_yaw">
  <implicitSpringDamper>1</implicitSpringDamper>
</gazebo>
  <gazebo>
  <plugin name="robotinterface" filename="libgazebo_yarp_robotinterface.so">
    <yarpRobotInterfaceConfigurationFile>model://ergoCub/conf/ergocub.xml</yarpRobotInterfaceConfigurationFile>
  </plugin>
</gazebo>
  <gazebo reference="l_arm_ft_sensor">
    <sensor name="l_arm_ft_sensor" type="force_torque">
      <always_on>1</always_on>
      <update_rate>100</update_rate>
      <force_torque>
        <frame>sensor</frame>
        <measure_direction>child_to_parent</measure_direction>
      </force_torque>
      <pose>0.0 0.0 0.0 -3.1415923328972943 2.923917580150936e-08 -1.5707962214346844</pose>
      <plugin name="left_arm_ft_plugin" filename="libgazebo_yarp_forcetorque.so">
  <yarpConfigurationFile>model://ergoCub/conf/FT/gazebo_ergocub_left_arm_ft.ini</yarpConfigurationFile>
</plugin>
    </sensor>
  </gazebo>
  <sensor name="l_arm_ft_sensor" type="force_torque">
    <parent joint="l_arm_ft_sensor"/>
    <force_torque>
      <frame>sensor</frame>
      <measure_direction>child_to_parent</measure_direction>
    </force_torque>
    <origin rpy="-3.1415923328972943 2.923917580150936e-08 -1.5707962214346844" xyz="0.0 0.0 0.0"/>
  </sensor>
  <gazebo reference="r_arm_ft_sensor">
    <sensor name="r_arm_ft_sensor" type="force_torque">
      <always_on>1</always_on>
      <update_rate>100</update_rate>
      <force_torque>
        <frame>sensor</frame>
        <measure_direction>child_to_parent</measure_direction>
      </force_torque>
      <pose>0.0 0.0 0.0 -3.1415924092528633 -2.2277470853981803e-08 1.5707964070692688</pose>
      <plugin name="right_arm_ft_plugin" filename="libgazebo_yarp_forcetorque.so">
  <yarpConfigurationFile>model://ergoCub/conf/FT/gazebo_ergocub_right_arm_ft.ini</yarpConfigurationFile>
</plugin>
    </sensor>
  </gazebo>
  <sensor name="r_arm_ft_sensor" type="force_torque">
    <parent joint="r_arm_ft_sensor"/>
    <force_torque>
      <frame>sensor</frame>
      <measure_direction>child_to_parent</measure_direction>
    </force_torque>
    <origin rpy="-3.1415924092528633 -2.2277470853981803e-08 1.5707964070692688" xyz="0.0 0.0 0.0"/>
  </sensor>
  <gazebo reference="l_leg_ft_sensor">
    <sensor name="l_leg_ft_sensor" type="force_torque">
      <always_on>1</always_on>
      <update_rate>100</update_rate>
      <force_torque>
        <frame>sensor</frame>
        <measure_direction>child_to_parent</measure_direction>
      </force_torque>
      <pose>0.0 0.0 0.0 3.141592653589793 -0.0 2.6179934742070086</pose>
      <plugin name="left_leg_ft_plugin" filename="libgazebo_yarp_forcetorque.so">
  <yarpConfigurationFile>model://ergoCub/conf/FT/gazebo_ergocub_left_leg_ft.ini</yarpConfigurationFile>
</plugin>
    </sensor>
  </gazebo>
  <sensor name="l_leg_ft_sensor" type="force_torque">
    <parent joint="l_leg_ft_sensor"/>
    <force_torque>
      <frame>sensor</frame>
      <measure_direction>child_to_parent</measure_direction>
    </force_torque>
    <origin rpy="3.141592653589793 -0.0 2.6179934742070086" xyz="0.0 0.0 0.0"/>
  </sensor>
  <gazebo reference="l_foot_front_ft_sensor">
    <sensor name="l_foot_front_ft_sensor" type="force_torque">
      <always_on>1</always_on>
      <update_rate>100</update_rate>
      <force_torque>
        <frame>sensor</frame>
        <measure_direction>parent_to_child</measure_direction>
      </force_torque>
      <pose>0.0 0.0 0.022299999999999986 0.0 -0.0 -2.0943952105869315</pose>
      <plugin name="left_foot_front_ft_plugin" filename="libgazebo_yarp_forcetorque.so">
  <yarpConfigurationFile>model://ergoCub/conf/FT/gazebo_ergocub_left_foot_front_ft.ini</yarpConfigurationFile>
</plugin>
    </sensor>
  </gazebo>
  <sensor name="l_foot_front_ft_sensor" type="force_torque">
    <parent joint="l_foot_front_ft_sensor"/>
    <force_torque>
      <frame>sensor</frame>
      <measure_direction>parent_to_child</measure_direction>
    </force_torque>
    <origin rpy="0.0 -0.0 -2.0943952105869315" xyz="0.0 0.0 0.022299999999999986"/>
  </sensor>
  <gazebo reference="l_foot_rear_ft_sensor">
    <sensor name="l_foot_rear_ft_sensor" type="force_torque">
      <always_on>1</always_on>
      <update_rate>100</update_rate>
      <force_torque>
        <frame>sensor</frame>
        <measure_direction>parent_to_child</measure_direction>
      </force_torque>
      <pose>0.0 0.0 0.022299999999999986 0.0 -0.0 -2.0943952105869315</pose>
      <plugin name="left_foot_rear_ft_plugin" filename="libgazebo_yarp_forcetorque.so">
  <yarpConfigurationFile>model://ergoCub/conf/FT/gazebo_ergocub_left_foot_rear_ft.ini</yarpConfigurationFile>
</plugin>
    </sensor>
  </gazebo>
  <sensor name="l_foot_rear_ft_sensor" type="force_torque">
    <parent joint="l_foot_rear_ft_sensor"/>
    <force_torque>
      <frame>sensor</frame>
      <measure_direction>parent_to_child</measure_direction>
    </force_torque>
    <origin rpy="0.0 -0.0 -2.0943952105869315" xyz="0.0 0.0 0.022299999999999986"/>
  </sensor>
  <gazebo reference="r_leg_ft_sensor">
    <sensor name="r_leg_ft_sensor" type="force_torque">
      <always_on>1</always_on>
      <update_rate>100</update_rate>
      <force_torque>
        <frame>sensor</frame>
        <measure_direction>child_to_parent</measure_direction>
      </force_torque>
      <pose>0.0 0.0 0.0 3.141592653589793 0.0 -2.6179934742070086</pose>
      <plugin name="right_leg_ft_plugin" filename="libgazebo_yarp_forcetorque.so">
  <yarpConfigurationFile>model://ergoCub/conf/FT/gazebo_ergocub_right_leg_ft.ini</yarpConfigurationFile>
</plugin>
    </sensor>
  </gazebo>
  <sensor name="r_leg_ft_sensor" type="force_torque">
    <parent joint="r_leg_ft_sensor"/>
    <force_torque>
      <frame>sensor</frame>
      <measure_direction>child_to_parent</measure_direction>
    </force_torque>
    <origin rpy="3.141592653589793 0.0 -2.6179934742070086" xyz="0.0 0.0 0.0"/>
  </sensor>
  <gazebo reference="r_foot_front_ft_sensor">
    <sensor name="r_foot_front_ft_sensor" type="force_torque">
      <always_on>1</always_on>
      <update_rate>100</update_rate>
      <force_torque>
        <frame>sensor</frame>
        <measure_direction>parent_to_child</measure_direction>
      </force_torque>
      <pose>0.0 0.0 0.022299999999999986 0.0 -0.0 -2.0943952105869315</pose>
      <plugin name="right_foot_front_ft_plugin" filename="libgazebo_yarp_forcetorque.so">
  <yarpConfigurationFile>model://ergoCub/conf/FT/gazebo_ergocub_right_foot_front_ft.ini</yarpConfigurationFile>
</plugin>
    </sensor>
  </gazebo>
  <sensor name="r_foot_front_ft_sensor" type="force_torque">
    <parent joint="r_foot_front_ft_sensor"/>
    <force_torque>
      <frame>sensor</frame>
      <measure_direction>parent_to_child</measure_direction>
    </force_torque>
    <origin rpy="0.0 -0.0 -2.0943952105869315" xyz="0.0 0.0 0.022299999999999986"/>
  </sensor>
  <gazebo reference="r_foot_rear_ft_sensor">
    <sensor name="r_foot_rear_ft_sensor" type="force_torque">
      <always_on>1</always_on>
      <update_rate>100</update_rate>
      <force_torque>
        <frame>sensor</frame>
        <measure_direction>parent_to_child</measure_direction>
      </force_torque>
      <pose>0.0 0.0 0.022299999999999986 0.0 -0.0 -2.0943952105869315</pose>
      <plugin name="right_foot_rear_ft_plugin" filename="libgazebo_yarp_forcetorque.so">
  <yarpConfigurationFile>model://ergoCub/conf/FT/gazebo_ergocub_right_foot_rear_ft.ini</yarpConfigurationFile>
</plugin>
    </sensor>
  </gazebo>
  <sensor name="r_foot_rear_ft_sensor" type="force_torque">
    <parent joint="r_foot_rear_ft_sensor"/>
    <force_torque>
      <frame>sensor</frame>
      <measure_direction>parent_to_child</measure_direction>
    </force_torque>
    <origin rpy="0.0 -0.0 -2.0943952105869315" xyz="0.0 0.0 0.022299999999999986"/>
  </sensor>
  <gazebo reference="head">
    <sensor name="head_imu_acc_1x1" type="imu">
      <always_on>1</always_on>
      <update_rate>100</update_rate>
      <pose>-0.004299998 -0.0055 0.03823499999999996 3.141592653589793 -0.0 1.5707963267948966</pose>
      <plugin name="ergocub_yarp_gazebo_plugin_IMU" filename="libgazebo_yarp_imu.so">
    <yarpConfigurationFile>model://ergoCub/conf/gazebo_ergocub_inertial.ini</yarpConfigurationFile>
</plugin>
    </sensor>
  </gazebo>
  <sensor name="head_imu_acc_1x1" type="accelerometer">
    <parent link="head"/>
    <origin rpy="3.141592653589793 -0.0 1.5707963267948966" xyz="-0.004299998 -0.0055 0.03823499999999996"/>
  </sensor>
  <gazebo reference="realsense">
    <sensor name="realsense_head_depth" type="depth">
      <always_on>1</always_on>
      <update_rate>30</update_rate>
      <pose>0.00751550026595621 0.010000000000000004 -4.911144457775407e-08 -1.5707962931078618 8.881784197001252e-16 -1.5707963267948954</pose>
      <camera name="intel_realsense_depth_camera">
  <pose>0 0 0 -1.57079 -1.57079 3.14159</pose>
  <horizontal_fov>1.57079</horizontal_fov>
  <distortion>
    <k1>0</k1>
    <k2>0</k2>
    <k3>0</k3>
    <p1>0</p1>
    <p2>0</p2>
    <center>319.5 239.5</center>
  </distortion>
  <image>
    <width>640</width>
    <height>480</height>
    <format>R8G8B8</format>
  </image>
  <clip>
    <near>0.175</near>
    <far>3000</far>
  </clip>
</camera>
      <visualize>false</visualize>
      <plugin name="ergocub_yarp_gazebo_plugin_depthCamera" filename="libgazebo_yarp_depthCamera.so">
    <yarpConfigurationFile>model://ergoCub/conf/sensors/gazebo_ergocub_rgbd_camera.ini</yarpConfigurationFile>
</plugin>
    </sensor>
  </gazebo>
  <sensor name="realsense_head_depth" type="depth">
    <parent link="realsense"/>
    <origin rpy="-1.5707962931078618 8.881784197001252e-16 -1.5707963267948954" xyz="0.00751550026595621 0.010000000000000004 -4.911144457775407e-08"/>
  </sensor>
  <gazebo reference="realsense">
    <sensor name="realsense_head_rgb" type="camera">
      <always_on>1</always_on>
      <update_rate>30</update_rate>
      <pose>0.00751550026595621 -0.0115 -4.911144457775407e-08 -1.5707962931078618 8.881784197001252e-16 -1.5707963267948954</pose>
      <camera name="intel_realsense_rgb_camera">
  <pose>0 0 0 -1.57079 -1.57079 3.14159</pose>
  <horizontal_fov>1.2217</horizontal_fov>
  <distortion>
    <k1>0</k1>
    <k2>0</k2>
    <k3>0</k3>
    <p1>0</p1>
    <p2>0</p2>
    <center>319.5 239.5</center>
  </distortion>
  <image>
    <width>640</width>
    <height>480</height>
    <format>R8G8B8</format>
  </image>
  <clip>
    <near>0.02</near>
    <far>3000</far>
  </clip>
</camera>
      <visualize>false</visualize>
      <plugin name="ergocub_yarp_gazebo_plugin_camera" filename="libgazebo_yarp_camera.so">
    <yarpConfigurationFile>model://ergoCub/conf/gazebo_ergocub_rgb_camera.ini</yarpConfigurationFile>
</plugin>
    </sensor>
  </gazebo>
  <sensor name="realsense_head_rgb" type="camera">
    <parent link="realsense"/>
    <origin rpy="-1.5707962931078618 8.881784197001252e-16 -1.5707963267948954" xyz="0.00751550026595621 -0.0115 -4.911144457775407e-08"/>
  </sensor>
  <gazebo reference="realsense">
    <sensor name="realsense_imu_acc_1x1" type="imu">
      <always_on>1</always_on>
      <update_rate>100</update_rate>
      <pose>0.00751550026595621 0.010000000000000004 -4.911144457775407e-08 -1.5707962931078618 8.881784197001252e-16 -1.5707963267948954</pose>
      <plugin name="ergocub_yarp_gazebo_plugin_IMU" filename="libgazebo_yarp_imu.so">
    <yarpConfigurationFile>model://ergoCub/conf/gazebo_ergocub_chest_inertial.ini</yarpConfigurationFile>
</plugin>
    </sensor>
  </gazebo>
  <sensor name="realsense_imu_acc_1x1" type="accelerometer">
    <parent link="realsense"/>
    <origin rpy="-1.5707962931078618 8.881784197001252e-16 -1.5707963267948954" xyz="0.00751550026595621 0.010000000000000004 -4.911144457775407e-08"/>
  </sensor>
  <gazebo>
    <pose>0.0 0.0 0.84 0.0 0.0 0.0</pose>
  </gazebo>
</robot>
